Workbook

Sheet README
A1: MonchMonch Financial Model — Spreadsheet Rebuild
A3: Version | B3: v3.0 rebuild (reverse-engineered from github.com/justinfowler925/monchmonch)
A4: Built | B4: 2026-05-20
A5: Source of truth | B5: monchmonch-calc/src/constants.js + model.js (commit on 2026-05-20)
A6: Status | B6: Pass 1 of 3 — INPUTS, CALC_RM, CALC_COGS complete; remaining tabs are scaffolds
A8: PURPOSE
B9: Replace the GitHub JavaScript calculator with a single editable workbook the user controls at the cell level. Every output traces to a formula; every formula traces to an INPUTS cell. No hardcoded numbers in calculation tabs.
A11: COLOR CONVENTION (industry-standard)
A12: Blue text | B12: Hardcoded input — change these to run scenarios
A13: Black text | B13: Formula on the same sheet
A14: Green text | B14: Formula linking to another sheet
A15: Yellow background | B15: Key assumption — review before using
A16: Orange background | B16: Known issue carried over from v3.0 JS code (see AUDIT tab)
A18: TAB MAP
A19: README | B19: This page
A20: INPUTS | B20: All parameters from constants.js, organized by section. Edit blue cells to change scenarios.
A21: CALC_RM | B21: Raw material cost rollup per ingredient at each tier (bars + electrolytes)
A22: CALC_COGS | B22: 7-tier COGS waterfall for bars and electrolytes. Shows v3.0 original AND a corrected version (overhead double-count removed).
A23: CALC_MONTHLY | B23: [Pass 2] Y1 monthly engine: demand → production → inventory → spoilage → channel revenue with proper ramp enforcement
A24: CALC_PL | B24: [Pass 2] 5-year P&L combining bars + ingredient licensing
A25: CALC_CASH | B25: [Pass 3] 60-month cash flow with proper working-capital changes (the piece v3.0 does not actually compute)
A26: DASHBOARD | B26: [Pass 3] Every number cited in the pitch deck, sourced to a formula on a calc tab
A27: AUDIT | B27: [Pass 3] Side-by-side: JS output vs. this workbook, plus documentation of every divergence and bug fix
A29: KNOWN ISSUES INHERITED FROM v3.0 JS CODE
A30: 1. Overhead double-counted | B30: fixedOverhead appears in both COGS (via ohAtTier) and OpEx (via annual fixed OH line). Corrected COGS column in CALC_COGS removes it from COGS; OpEx keeps the full annual figure.
A31: 2. COGS overhead dimensionally off | B31: Original formula: fixedOverhead / midVol[tier]. Divides a monthly $ by an annual unit count. Magnitude is arbitrary; direction (scale-down) is the only correct piece.
A32: 3. Annual revenue ignores ramp | B32: Monthly calc respects channel rampMonths; annual calc does not. Annual P&L revenue is overstated relative to sum of monthly figures.
A33: 4. Cash flow is just cumulative EBITDA | B33: No WC changes, no AR/AP, no inventory build. The "$968K Y2 trough" in the deck is annual EBITDA spread evenly across months — a smoothed approximation, not a real cash projection.
A34: 5. Bar BOM is incomplete | B34: Many bar ingredients in constants.js have qty=0 (Milk Protein Isolate, Tapioca Fiber, IMO, Veg Glycerin, Cocoa Butter, Sunflower Lecithin, Salt, Cocoa Soy Crisp). The bar RM cost is understated relative to a real recipe.
A35: 6. Deck COGS numbers off-model | B35: Deck cites $1.59 bar COGS at 25K units and $1.35 at 100K. v3.0 computes $1.83 and $1.64 respectively. Deck gross margin math is self-consistent but the COGS values are not derived from the model.
A37: HOW TO USE
A38: 2. Edit INPUTS | B38: Change any blue cell. The CALC tabs and DASHBOARD will update.
A39: 3. Check AUDIT | B39: Before sharing with investors, review the AUDIT tab to confirm which numbers match v3.0 and which deliberately diverge.

Sheet INPUTS
A1: INPUTS — All Parameters (v3.0 mirror)
A3: GLOBAL ASSUMPTIONS
A4: Parameter | B4: Value | H4: Notes
A5: Returns / Allowances % | B5: 0.02 | H5: 2% of gross revenue across all channels
A6: Target Days of Inventory | B6: 30 | H6: NOT actually used in v3.0 logic — phantom input
A7: Safety Stock % | B7: 0.15 | H7: Target end-of-month inventory as % of that month adj demand
A8: Warehousing $/unit/mo | B8: 0.05
A9: Insurance % of inv value | B9: 0.02 | H9: Not used in v3.0 carrying cost calc — phantom input
A10: Cost of Capital % | B10: 0.08 | H10: Not used in v3.0 carrying cost calc — phantom input
A11: Spoilage rate Bars (%/mo) | B11: 0.005
A12: Spoilage rate Elec (%/mo) | B12: 0.002
A13: Spoilage cost multiplier | B13: 3 | H13: 3x: covers unit loss + production cost + disposal
A14: Carrying cost rate | B14: 0.1 | H14: Applied to warehousing $ × units; insurance/CoC inputs unused
A16: LABOR & OVERHEAD
A17: Role | B17: Headcount | C17: Rate $/hr | D17: Hours/Run | E17: Variable? | H17: Notes
A18: Production Operator | B18: 2 | C18: 22 | D18: 8 | E18: Yes
A19: QA Inspector | B19: 1 | C19: 28 | D19: 4 | E19: Yes
A20: Warehouse | B20: 1 | C20: 18 | D20: 6 | E20: Yes
A21: Production Manager | B21: 1 | C21: 45 | D21: 8 | E21: No
A22: Total labor cost per run | B22: =SUMPRODUCT(B18:B21,C18:C21,D18:D21) -> 932 | H22: Sum(headcount × rate × hours)
A24: Direct labor $/unit (fallback) | B24: 0.3 | H24: Used only if laborRoles empty
A25: Fixed Overhead $/mo | B25: 5000
A26: Equipment Amort $/mo | B26: 2000
A27: G&A $/mo | B27: 6000
A29: LEGACY PRICING (reference only, NOT used in v3.0 — see CHANNELS below)
A30: Bar MSRP | B30: 3.5
A31: Bar Trade/Wholesale | B31: 1.75
A32: Electrolyte MSRP | B32: 2.25
A33: Electrolyte Trade | B33: 1.13
A34: DTC Fulfillment $/unit (legacy) | B34: 2.5
A35: Wholesale Freight $/unit (legacy) | B35: 1
A36: Marketing % of revenue (legacy) | B36: 0.1
A37: Marketing fixed annual (legacy) | B37: 150000
A39: CHANNELS (6 channels — drives v3.0 revenue + channel costs)
A40: Channel | B40: Active | C40: %Alloc | D40: Bar Price | E40: Elec Price | F40: Cost/Unit | G40: Ramp Months | H40: Max Monthly Units
A41: DTC (Website) | B41: Yes | C41: 0.4 | D41: 3.5 | E41: 2.25 | F41: 0.85 | G41: 0 | H41: 30000
A42: Amazon | B42: Yes | C42: 0.2 | D42: 2.8 | E42: 1.8 | F42: 0.55 | G42: 2 | H42: 18000
A43: Big Box Retail | B43: No | C43: 0 | D43: 1.75 | E43: 1.13 | F43: 0.45 | G43: 24 | H43: 40000
A44: Natural/Specialty | B44: Yes | C44: 0.15 | D44: 2.1 | E44: 1.35 | F44: 0.42 | G44: 4 | H44: 9000
A45: Vitamin Shops | B45: Yes | C45: 0.08 | D45: 1.95 | E45: 1.25 | F45: 0.3 | G45: 3 | H45: 4500
...

Sheet CALC_RM
A1: CALC_RM — Raw Material Cost Rollup
A3: Per-unit RM cost at each tier price = qty × $/lb
A5: BAR RAW MATERIALS
A6: Material | B6: Qty/unit | C6: $/lb T1 | D6: $/lb T2 | E6: $/lb T3 | F6: Cost T1 | G6: Cost T2 | H6: Cost T3
A7: =INPUTS!A74 -> Flavoring Orig | B7: =INPUTS!B74 -> 0.01 | C7: =INPUTS!C74 -> 4 | D7: =INPUTS!D74 -> 3.5 | E7: =INPUTS!E74 -> 3 | F7: =B7*C7 -> 0.04 | G7: =B7*D7 -> 0.035 | H7: =B7*E7 -> 0.03
A8: =INPUTS!A75 -> Flavoring Berry | B8: =INPUTS!B75 -> 0.012 | C8: =INPUTS!C75 -> 5 | D8: =INPUTS!D75 -> 4.33 | E8: =INPUTS!E75 -> 3.75 | F8: =B8*C8 -> 0.06 | G8: =B8*D8 -> 0.05196 | H8: =B8*E8 -> 0.045
A9: =INPUTS!A76 -> Wrapper | B9: =INPUTS!B76 -> 1 | C9: =INPUTS!C76 -> 0.08 | D9: =INPUTS!D76 -> 0.061 | E9: =INPUTS!E76 -> 0.05 | F9: =B9*C9 -> 0.08 | G9: =B9*D9 -> 0.061 | H9: =B9*E9 -> 0.05
A10: =INPUTS!A77 -> Outer Box | B10: =INPUTS!B77 -> 0.083 | C10: =INPUTS!C77 -> 0.36 | D10: =INPUTS!D77 -> 0.3 | E10: =INPUTS!E77 -> 0.24 | F10: =B10*C10 -> 0.02988 | G10: =B10*D10 -> 0.0249 | H10: =B10*E10 -> 0.01992
A11: =INPUTS!A78 -> Whey Protein | B11: =INPUTS!B78 -> 0.044 | C11: =INPUTS!C78 -> 10 | D11: =INPUTS!D78 -> 9 | E11: =INPUTS!E78 -> 8 | F11: =B11*C11 -> 0.44 | G11: =B11*D11 -> 0.396 | H11: =B11*E11 -> 0.352
A12: =INPUTS!A79 -> Milk Protein Isolate | B12: =INPUTS!B79 -> 0 | C12: =INPUTS!C79 -> 10 | D12: =INPUTS!D79 -> 9 | E12: =INPUTS!E79 -> 8 | F12: =B12*C12 -> 0 | G12: =B12*D12 -> 0 | H12: =B12*E12 -> 0
A13: =INPUTS!A80 -> Tapioca Fiber | B13: =INPUTS!B80 -> 0 | C13: =INPUTS!C80 -> 0 | D13: =INPUTS!D80 -> 0 | E13: =INPUTS!E80 -> 0 | F13: =B13*C13 -> 0 | G13: =B13*D13 -> 0 | H13: =B13*E13 -> 0
A14: =INPUTS!A81 -> IMO | B14: =INPUTS!B81 -> 0 | C14: =INPUTS!C81 -> 0 | D14: =INPUTS!D81 -> 0 | E14: =INPUTS!E81 -> 0 | F14: =B14*C14 -> 0 | G14: =B14*D14 -> 0 | H14: =B14*E14 -> 0
A15: =INPUTS!A82 -> Vegetable Glycerin | B15: =INPUTS!B82 -> 0 | C15: =INPUTS!C82 -> 0 | D15: =INPUTS!D82 -> 0 | E15: =INPUTS!E82 -> 0 | F15: =B15*C15 -> 0 | G15: =B15*D15 -> 0 | H15: =B15*E15 -> 0
A16: =INPUTS!A83 -> Cocoa Butter | B16: =INPUTS!B83 -> 0 | C16: =INPUTS!C83 -> 0 | D16: =INPUTS!D83 -> 0 | E16: =INPUTS!E83 -> 0 | F16: =B16*C16 -> 0 | G16: =B16*D16 -> 0 | H16: =B16*E16 -> 0
A17: =INPUTS!A84 -> Sunflower Lecithin | B17: =INPUTS!B84 -> 0 | C17: =INPUTS!C84 -> 0 | D17: =INPUTS!D84 -> 0 | E17: =INPUTS!E84 -> 0 | F17: =B17*C17 -> 0 | G17: =B17*D17 -> 0 | H17: =B17*E17 -> 0
A18: =INPUTS!A85 -> Stevia Reb M | B18: =INPUTS!B85 -> 0.025 | C18: =INPUTS!C85 -> 2.4 | D18: =INPUTS!D85 -> 2 | E18: =INPUTS!E85 -> 1.6 | F18: =B18*C18 -> 0.06 | G18: =B18*D18 -> 0.05 | H18: =B18*E18 -> 0.04
... A20: =INPUTS!A87 -> Cocoa Soy Crisp | B20: =INPUTS!B87 -> 0 | C20: =INPUTS!C87 -> 0 | D20: =INPUTS!D87 -> 0 | E20: =INPUTS!E87 -> 0 | F20: =B20*C20 -> 0 | G20: =B20*D20 -> 0 | H20: =B20*E20 -> 0
A21: BAR RM TOTAL ($/unit) | F21: =SUM(F7:F20) -> 0.70988 | G21: =SUM(G7:G20) -> 0.61886 | H21: =SUM(H7:H20) -> 0.53692
A23: ELECTROLYTE RAW MATERIALS
A24: Material | B24: Qty/unit | C24: $/lb T1 | D24: $/lb T2 | E24: $/lb T3 | F24: Cost T1 | G24: Cost T2 | H24: Cost T3
A25: =INPUTS!A91 -> Ascorbic Acid | B25: =INPUTS!B91 -> 0.015 | C25: =INPUTS!C91 -> 6.67 | D25: =INPUTS!D91 -> 5.5 | E25: =INPUTS!E91 -> 4.5 | F25: =B25*C25 -> 0.10005 | G25: =B25*D25 -> 0.0825 | H25: =B25*E25 -> 0.0675
A26: =INPUTS!A92 -> Monch Fiber | B26: =INPUTS!B92 -> 0.008 | C26: =INPUTS!C92 -> 5 | D26: =INPUTS!D92 -> 4 | E26: =INPUTS!E92 -> 3.25 | F26: =B26*C26 -> 0.04 | G26: =B26*D26 -> 0.032 | H26: =B26*E26 -> 0.026
A27: =INPUTS!A93 -> Citric Acid | B27: =INPUTS!B93 -> 0.005 | C27: =INPUTS!C93 -> 6 | D27: =INPUTS!D93 -> 5 | E27: =INPUTS!E93 -> 4 | F27: =B27*C27 -> 0.03 | G27: =B27*D27 -> 0.025 | H27: =B27*E27 -> 0.02
A28: =INPUTS!A94 -> Salt | B28: =INPUTS!B94 -> 0.003 | C28: =INPUTS!C94 -> 0.5 | D28: =INPUTS!D94 -> 0.4 | E28: =INPUTS!E94 -> 0.33 | F28: =B28*C28 -> 0.0015 | G28: =B28*D28 -> 0.0012 | H28: =B28*E28 -> 0.00099
A29: =INPUTS!A95 -> Potassium Cl | B29: =INPUTS!B95 -> 0.005 | C29: =INPUTS!C95 -> 4 | D29: =INPUTS!D95 -> 3.5 | E29: =INPUTS!E95 -> 3 | F29: =B29*C29 -> 0.02 | G29: =B29*D29 -> 0.0175 | H29: =B29*E29 -> 0.015
A30: =INPUTS!A96 -> Magnesium Malate | B30: =INPUTS!B96 -> 0.008 | C30: =INPUTS!C96 -> 5 | D30: =INPUTS!D96 -> 4.25 | E30: =INPUTS!E96 -> 3.5 | F30: =B30*C30 -> 0.04 | G30: =B30*D30 -> 0.034 | H30: =B30*E30 -> 0.028
A31: =INPUTS!A97 -> Purified Stevia | B31: =INPUTS!B97 -> 0.003 | C31: =INPUTS!C97 -> 1.33 | D31: =INPUTS!D97 -> 1 | E31: =INPUTS!E97 -> 0.83 | F31: =B31*C31 -> 0.00399 | G31: =B31*D31 -> 0.003 | H31: =B31*E31 -> 0.00249
A32: =INPUTS!A98 -> Flavoring | B32: =INPUTS!B98 -> 0.01 | C32: =INPUTS!C98 -> 4 | D32: =INPUTS!D98 -> 3.5 | E32: =INPUTS!E98 -> 3 | F32: =B32*C32 -> 0.04 | G32: =B32*D32 -> 0.035 | H32: =B32*E32 -> 0.03
A33: =INPUTS!A99 -> Sachet Pkg | B33: =INPUTS!B99 -> 1 | C33: =INPUTS!C99 -> 0.05 | D33: =INPUTS!D99 -> 0.04 | E33: =INPUTS!E99 -> 0.03 | F33: =B33*C33 -> 0.05 | G33: =B33*D33 -> 0.04 | H33: =B33*E33 -> 0.03
A34: ELEC RM TOTAL ($/unit) | F34: =SUM(F25:F33) -> 0.32554 | G34: =SUM(G25:G33) -> 0.2702 | H34: =SUM(H25:H33) -> 0.21998
A36: MOQ COMMITMENT SUMMARY (at T1 prices)
A37: Product | B37: Sum of MOQ × T1 | H37: Notes
A38: Bars (RM only) | B38: =SUMPRODUCT(INPUTS!F74:F87,INPUTS!C74:C87) -> 5225 | H38: Total $ if you buy every ingredient at its MOQ at T1 prices
A39: Electrolytes (RM only) | B39: =SUMPRODUCT(INPUTS!F91:F99,INPUTS!C91:C99) -> 2150

Sheet CALC_COGS
A1: CALC_COGS — 7-Tier COGS Waterfall (v3.0 original + corrected)
A3: Original total = v3.0 JS formula (includes overhead double-count). Corrected total = overhead removed from COGS (kept in OpEx only).
A5: BAR COGS WATERFALL — by Operating Volume Tier
A6: Tier | B6: Label | C6: Mid Vol | D6: RM | E6: Labor | F6: Overhead (v3.0) | G6: Co-Man | H6: Packaging | I6: TOTAL (v3.0) | K6: TOTAL (corrected)
A7: =INPUTS!A51 -> 1 | B7: =INPUTS!B51 -> 1–999 | C7: =INPUTS!D51 -> 500 | D7: =IF(A7<=2,CALC_RM!$F$21,IF(A7<=4,CALC_RM!$G$21,CALC_RM!$H$21)) -> 0.70988 | E7: =(INPUTS!$B$22/C7)*INPUTS!G51 -> 1.864 | F7: =INPUTS!$B$25/C7 -> 10 | G7: =INPUTS!E51 -> 1.35 | H7: 0 | I7: =D7+E7+F7+G7+H7 -> 13.92388 | K7: =D7+E7+G7+H7 -> 3.92388
A8: =INPUTS!A52 -> 2 | B8: =INPUTS!B52 -> 1K–10K | C8: =INPUTS!D52 -> 5000 | D8: =IF(A8<=2,CALC_RM!$F$21,IF(A8<=4,CALC_RM!$G$21,CALC_RM!$H$21)) -> 0.70988 | E8: =(INPUTS!$B$22/C8)*INPUTS!G52 -> 0.1398 | F8: =INPUTS!$B$25/C8 -> 1 | G8: =INPUTS!E52 -> 1.2 | H8: 0 | I8: =D8+E8+F8+G8+H8 -> 3.04968 | K8: =D8+E8+G8+H8 -> 2.04968
A9: =INPUTS!A53 -> 3 | B9: =INPUTS!B53 -> 10K–100K | C9: =INPUTS!D53 -> 50000 | D9: =IF(A9<=2,CALC_RM!$F$21,IF(A9<=4,CALC_RM!$G$21,CALC_RM!$H$21)) -> 0.61886 | E9: =(INPUTS!$B$22/C9)*INPUTS!G53 -> 0.00932 | F9: =INPUTS!$B$25/C9 -> 0.1 | G9: =INPUTS!E53 -> 1.1 | H9: 0 | I9: =D9+E9+F9+G9+H9 -> 1.82818 | K9: =D9+E9+G9+H9 -> 1.72818
A10: =INPUTS!A54 -> 4 | B10: =INPUTS!B54 -> 100K–500K | C10: =INPUTS!D54 -> 250000 | D10: =IF(A10<=2,CALC_RM!$F$21,IF(A10<=4,CALC_RM!$G$21,CALC_RM!$H$21)) -> 0.61886 | E10: =(INPUTS!$B$22/C10)*INPUTS!G54 -> 0.0013048 | F10: =INPUTS!$B$25/C10 -> 0.02 | G10: =INPUTS!E54 -> 1 | H10: 0 | I10: =D10+E10+F10+G10+H10 -> 1.6401648 | K10: =D10+E10+G10+H10 -> 1.6201648
A11: =INPUTS!A55 -> 5 | B11: =INPUTS!B55 -> 500K–1M | C11: =INPUTS!D55 -> 750000 | D11: =IF(A11<=2,CALC_RM!$F$21,IF(A11<=4,CALC_RM!$G$21,CALC_RM!$H$21)) -> 0.53692 | E11: =(INPUTS!$B$22/C11)*INPUTS!G55 -> 0.00031066667 | F11: =INPUTS!$B$25/C11 -> 0.0066666667 | G11: =INPUTS!E55 -> 0.92 | H11: 0 | I11: =D11+E11+F11+G11+H11 -> 1.4638973 | K11: =D11+E11+G11+H11 -> 1.4572307
A12: =INPUTS!A56 -> 6 | B12: =INPUTS!B56 -> 1M–5M | C12: =INPUTS!D56 -> 2500000 | D12: =IF(A12<=2,CALC_RM!$F$21,IF(A12<=4,CALC_RM!$G$21,CALC_RM!$H$21)) -> 0.53692 | E12: =(INPUTS!$B$22/C12)*INPUTS!G56 -> 6.7104e-05 | F12: =INPUTS!$B$25/C12 -> 0.002 | G12: =INPUTS!E56 -> 0.85 | H12: 0 | I12: =D12+E12+F12+G12+H12 -> 1.3889871 | K12: =D12+E12+G12+H12 -> 1.3869871
A13: =INPUTS!A57 -> 7 | B13: =INPUTS!B57 -> 5M+ | C13: =INPUTS!D57 -> 7500000 | D13: =IF(A13<=2,CALC_RM!$F$21,IF(A13<=4,CALC_RM!$G$21,CALC_RM!$H$21)) -> 0.53692 | E13: =(INPUTS!$B$22/C13)*INPUTS!G57 -> 1.4912e-05 | F13: =INPUTS!$B$25/C13 -> 0.00066666667 | G13: =INPUTS!E57 -> 0.8 | H13: 0 | I13: =D13+E13+F13+G13+H13 -> 1.3376016 | K13: =D13+E13+G13+H13 -> 1.3369349
A16: ELECTROLYTE COGS WATERFALL — by Operating Volume Tier
A17: Tier | B17: Label | C17: Mid Vol | D17: RM | E17: Labor | F17: Overhead (v3.0) | G17: Co-Man | H17: Packaging | I17: TOTAL (v3.0) | K17: TOTAL (corrected)
A18: =INPUTS!A51 -> 1 | B18: =INPUTS!B51 -> 1–999 | C18: =INPUTS!D51 -> 500 | D18: =IF(A18<=2,CALC_RM!$F$34,IF(A18<=4,CALC_RM!$G$34,CALC_RM!$H$34)) -> 0.32554 | E18: =(INPUTS!$B$22/C18)*INPUTS!G51 -> 1.864 | F18: =INPUTS!$B$25/C18 -> 10 | G18: =INPUTS!F51 -> 0.45 | H18: 0 | I18: =D18+E18+F18+G18+H18 -> 12.63954 | K18: =D18+E18+G18+H18 -> 2.63954
A19: =INPUTS!A52 -> 2 | B19: =INPUTS!B52 -> 1K–10K | C19: =INPUTS!D52 -> 5000 | D19: =IF(A19<=2,CALC_RM!$F$34,IF(A19<=4,CALC_RM!$G$34,CALC_RM!$H$34)) -> 0.32554 | E19: =(INPUTS!$B$22/C19)*INPUTS!G52 -> 0.1398 | F19: =INPUTS!$B$25/C19 -> 1 | G19: =INPUTS!F52 -> 0.4 | H19: 0 | I19: =D19+E19+F19+G19+H19 -> 1.86534 | K19: =D19+E19+G19+H19 -> 0.86534
A20: =INPUTS!A53 -> 3 | B20: =INPUTS!B53 -> 10K–100K | C20: =INPUTS!D53 -> 50000 | D20: =IF(A20<=2,CALC_RM!$F$34,IF(A20<=4,CALC_RM!$G$34,CALC_RM!$H$34)) -> 0.2702 | E20: =(INPUTS!$B$22/C20)*INPUTS!G53 -> 0.00932 | F20: =INPUTS!$B$25/C20 -> 0.1 | G20: =INPUTS!F53 -> 0.35 | H20: 0 | I20: =D20+E20+F20+G20+H20 -> 0.72952 | K20: =D20+E20+G20+H20 -> 0.62952
A21: =INPUTS!A54 -> 4 | B21: =INPUTS!B54 -> 100K–500K | C21: =INPUTS!D54 -> 250000 | D21: =IF(A21<=2,CALC_RM!$F$34,IF(A21<=4,CALC_RM!$G$34,CALC_RM!$H$34)) -> 0.2702 | E21: =(INPUTS!$B$22/C21)*INPUTS!G54 -> 0.0013048 | F21: =INPUTS!$B$25/C21 -> 0.02 | G21: =INPUTS!F54 -> 0.3 | H21: 0 | I21: =D21+E21+F21+G21+H21 -> 0.5915048 | K21: =D21+E21+G21+H21 -> 0.5715048
A22: =INPUTS!A55 -> 5 | B22: =INPUTS!B55 -> 500K–1M | C22: =INPUTS!D55 -> 750000 | D22: =IF(A22<=2,CALC_RM!$F$34,IF(A22<=4,CALC_RM!$G$34,CALC_RM!$H$34)) -> 0.21998 | E22: =(INPUTS!$B$22/C22)*INPUTS!G55 -> 0.00031066667 | F22: =INPUTS!$B$25/C22 -> 0.0066666667 | G22: =INPUTS!F55 -> 0.27 | H22: 0 | I22: =D22+E22+F22+G22+H22 -> 0.49695733 | K22: =D22+E22+G22+H22 -> 0.49029067
A23: =INPUTS!A56 -> 6 | B23: =INPUTS!B56 -> 1M–5M | C23: =INPUTS!D56 -> 2500000 | D23: =IF(A23<=2,CALC_RM!$F$34,IF(A23<=4,CALC_RM!$G$34,CALC_RM!$H$34)) -> 0.21998 | E23: =(INPUTS!$B$22/C23)*INPUTS!G56 -> 6.7104e-05 | F23: =INPUTS!$B$25/C23 -> 0.002 | G23: =INPUTS!F56 -> 0.25 | H23: 0 | I23: =D23+E23+F23+G23+H23 -> 0.4720471 | K23: =D23+E23+G23+H23 -> 0.4700471
A24: =INPUTS!A57 -> 7 | B24: =INPUTS!B57 -> 5M+ | C24: =INPUTS!D57 -> 7500000 | D24: =IF(A24<=2,CALC_RM!$F$34,IF(A24<=4,CALC_RM!$G$34,CALC_RM!$H$34)) -> 0.21998 | E24: =(INPUTS!$B$22/C24)*INPUTS!G57 -> 1.4912e-05 | F24: =INPUTS!$B$25/C24 -> 0.00066666667 | G24: =INPUTS!F57 -> 0.22 | H24: 0 | I24: =D24+E24+F24+G24+H24 -> 0.44066158 | K24: =D24+E24+G24+H24 -> 0.43999491
A27: NOTES
A28: • Original column matches v3.0 JS exactly. Use this for reconciliation.
A29: • Corrected column removes overhead from COGS (it remains in OpEx as the annualized fixed-OH line, so it doesn't disappear from the P&L — it just isn't double-counted).
A30: • RM tier mapping (1-2 → T1 price, 3-4 → T2 price, 5-7 → T3 price) matches model.js line 39.
A31: • Labor formula = (sum of headcount×rate×hours)/midVol × tier scale factor. Matches laborAtTier() in model.js.
A32: • Packaging is currently 0 across all tiers because all barPackaging/elecPackaging items in constants.js have costPerUnit=0.

Sheet CALC_MONTHLY
A1: CALC_MONTHLY — Y1 Monthly Engine
A2: Mirrors computeY1Monthly() in model.js (lines 83-125). Channel active in month m when m > rampMonths (1-indexed). Caveat: demand allocated to a channel during its ramp period is lost — totalAlloc is computed over all active channels regardless of ramp state. This is a v3.0 behavior the spreadsheet faithfully reproduces.
A3: Total Active %Alloc: | B3: =SUMIFS(INPUTS!C41:C46,INPUTS!B41:B46,"Yes") -> 1 | D3: Sum of pctAlloc where channel.active="Yes". Normalizer for per-channel allocation.
A5: Month # | B5: 1 | C5: 2 | D5: 3 | E5: 4 | F5: 5 | G5: 6 | H5: 7 | I5: 8 | J5: 9 | K5: 10 | L5: 11 | M5: 12 | N5: Y1 TOTAL
A6: Month Name | B6: Jan | C6: Feb | D6: Mar | E6: Apr | F6: May | G6: Jun | H6: Jul | I6: Aug | J6: Sep | K6: Oct | L6: Nov | M6: Dec
A7: Bar Adj Demand (Base × Season) | B7: =ROUND(INPUTS!B103*INPUTS!D103,0) -> 2300 | C7: =ROUND(INPUTS!B104*INPUTS!D104,0) -> 3300 | D7: =ROUND(INPUTS!B105*INPUTS!D105,0) -> 4200 | E7: =ROUND(INPUTS!B106*INPUTS!D106,0) -> 4750 | F7: =ROUND(INPUTS!B107*INPUTS!D107,0) -> 4950 | G7: =ROUND(INPUTS!B108*INPUTS!D108,0) -> 5700 | H7: =ROUND(INPUTS!B109*INPUTS!D109,0) -> 6500 | I7: =ROUND(INPUTS!B110*INPUTS!D110,0) -> 7000 | J7: =ROUND(INPUTS!B111*INPUTS!D111,0) -> 7125 | K7: =ROUND(INPUTS!B112*INPUTS!D112,0) -> 7600 | L7: =ROUND(INPUTS!B113*INPUTS!D113,0) -> 8500 | M7: =ROUND(INPUTS!B114*INPUTS!D114,0) -> 9000 | N7: =SUM(B7:M7) -> 70925
A8: Elec Adj Demand (Base × Season) | B8: =ROUND(INPUTS!C103*INPUTS!E103,0) -> 1275 | C8: =ROUND(INPUTS!C104*INPUTS!E104,0) -> 2125 | D8: =ROUND(INPUTS!C105*INPUTS!E105,0) -> 3150 | E8: =ROUND(INPUTS!C106*INPUTS!E106,0) -> 4500 | F8: =ROUND(INPUTS!C107*INPUTS!E107,0) -> 5500 | G8: =ROUND(INPUTS!C108*INPUTS!E108,0) -> 6600 | H8: =ROUND(INPUTS!C109*INPUTS!E109,0) -> 7500 | I8: =ROUND(INPUTS!C110*INPUTS!E110,0) -> 7800 | J8: =ROUND(INPUTS!C111*INPUTS!E111,0) -> 7350 | K8: =ROUND(INPUTS!C112*INPUTS!E112,0) -> 6750 | L8: =ROUND(INPUTS!C113*INPUTS!E113,0) -> 6800 | M8: =ROUND(INPUTS!C114*INPUTS!E114,0) -> 7225 | N8: =SUM(B8:M8) -> 66575
A10: INVENTORY & PRODUCTION — BARS
A11: Bar Beg Inv | B11: 0 | C11: =B15 -> 345 | D11: =C15 -> 493 | E11: =D15 -> 628 | F11: =E15 -> 710 | G11: =F15 -> 739 | H11: =G15 -> 851 | I11: =H15 -> 971 | J11: =I15 -> 1045 | ... M11: =L15 -> 1269
A12: Bar Safety Target | B12: =CEILING(B7*INPUTS!$B$7,1) -> 345 | C12: =CEILING(C7*INPUTS!$B$7,1) -> 495 | D12: =CEILING(D7*INPUTS!$B$7,1) -> 630 | E12: =CEILING(E7*INPUTS!$B$7,1) -> 713 | F12: =CEILING(F7*INPUTS!$B$7,1) -> 743 | G12: =CEILING(G7*INPUTS!$B$7,1) -> 855 | H12: =CEILING(H7*INPUTS!$B$7,1) -> 975 | I12: =CEILING(I7*INPUTS!$B$7,1) -> 1050 | ... M12: =CEILING(M7*INPUTS!$B$7,1) -> 1350
A13: Bar Production | B13: =MAX(B7+B12-B11,0) -> 2645 | C13: =MAX(C7+C12-C11,0) -> 3450 | D13: =MAX(D7+D12-D11,0) -> 4337 | E13: =MAX(E7+E12-E11,0) -> 4835 | F13: =MAX(F7+F12-F11,0) -> 4983 | G13: =MAX(G7+G12-G11,0) -> 5816 | H13: =MAX(H7+H12-H11,0) -> 6624 | I13: =MAX(I7+I12-I11,0) -> 7079 | ... M13: =MAX(M7+M12-M11,0) -> 9081 | N13: =SUM(B13:M13) -> 72315
A14: Bar Spoilage (units) | B14: =ROUND(B11*INPUTS!$B$11,0) -> 0 | C14: =ROUND(C11*INPUTS!$B$11,0) -> 2 | D14: =ROUND(D11*INPUTS!$B$11,0) -> 2 | E14: =ROUND(E11*INPUTS!$B$11,0) -> 3 | F14: =ROUND(F11*INPUTS!$B$11,0) -> 4 | G14: =ROUND(G11*INPUTS!$B$11,0) -> 4 | H14: =ROUND(H11*INPUTS!$B$11,0) -> 4 | I14: =ROUND(I11*INPUTS!$B$11,0) -> 5 | ... M14: =ROUND(M11*INPUTS!$B$11,0) -> 6 | N14: =SUM(B14:M14) -> 46
A15: Bar End Inv | B15: =B11+B13-B7-B14 -> 345 | C15: =C11+C13-C7-C14 -> 493 | D15: =D11+D13-D7-D14 -> 628 | E15: =E11+E13-E7-E14 -> 710 | F15: =F11+F13-F7-F14 -> 739 | G15: =G11+G13-G7-G14 -> 851 | H15: =H11+H13-H7-H14 -> 971 | I15: =I11+I13-I7-I14 -> 1045 | ... M15: =M11+M13-M7-M14 -> 1344
A16: Bar MOQ Alert | B16: =IF(AND(B13>0,B13<INPUTS!$B$142),"BELOW MOQ","") -> BELOW MOQ | C16: =IF(AND(C13>0,C13<INPUTS!$B$142),"BELOW MOQ","") -> BELOW MOQ | D16: =IF(AND(D13>0,D13<INPUTS!$B$142),"BELOW MOQ","") -> BELOW MOQ | E16: =IF(AND(E13>0,E13<INPUTS!$B$142),"BELOW MOQ","") -> BELOW MOQ | F16: =IF(AND(F13>0,F13<INPUTS!$B$142),"BELOW MOQ","") -> BELOW MOQ | G16: =IF(AND(G13>0,G13<INPUTS!$B$142),"BELOW MOQ","") | H16: =IF(AND(H13>0,H13<INPUTS!$B$142),"BELOW MOQ","") | I16: =IF(AND(I13>0,I13<INPUTS!$B$142),"BELOW MOQ","") | ... M16: =IF(AND(M13>0,M13<INPUTS!$B$142),"BELOW MOQ","")
A18: INVENTORY & PRODUCTION — ELECTROLYTES
A19: Elec Beg Inv | B19: 0 | C19: =B23 -> 192 | D19: =C23 -> 319 | E19: =D23 -> 472 | F19: =E23 -> 674 | G19: =F23 -> 824 | H19: =G23 -> 988 | I19: =H23 -> 1123 | J19: =I23 -> 1168 | ... M19: =L23 -> 1018
A20: Elec Safety Target | B20: =CEILING(B8*INPUTS!$B$7,1) -> 192 | C20: =CEILING(C8*INPUTS!$B$7,1) -> 319 | D20: =CEILING(D8*INPUTS!$B$7,1) -> 473 | E20: =CEILING(E8*INPUTS!$B$7,1) -> 675 | F20: =CEILING(F8*INPUTS!$B$7,1) -> 825 | G20: =CEILING(G8*INPUTS!$B$7,1) -> 990 | H20: =CEILING(H8*INPUTS!$B$7,1) -> 1125 | I20: =CEILING(I8*INPUTS!$B$7,1) -> 1170 | ... M20: =CEILING(M8*INPUTS!$B$7,1) -> 1084
A21: Elec Production | B21: =MAX(B8+B20-B19,0) -> 1467 | C21: =MAX(C8+C20-C19,0) -> 2252 | D21: =MAX(D8+D20-D19,0) -> 3304 | E21: =MAX(E8+E20-E19,0) -> 4703 | F21: =MAX(F8+F20-F19,0) -> 5651 | G21: =MAX(G8+G20-G19,0) -> 6766 | H21: =MAX(H8+H20-H19,0) -> 7637 | I21: =MAX(I8+I20-I19,0) -> 7847 | ... M21: =MAX(M8+M20-M19,0) -> 7291 | N21: =SUM(B21:M21) -> 67674
A22: Elec Spoilage (units) | B22: =ROUND(B19*INPUTS!$B$12,0) -> 0 | C22: =ROUND(C19*INPUTS!$B$12,0) -> 0 | D22: =ROUND(D19*INPUTS!$B$12,0) -> 1 | E22: =ROUND(E19*INPUTS!$B$12,0) -> 1 | F22: =ROUND(F19*INPUTS!$B$12,0) -> 1 | G22: =ROUND(G19*INPUTS!$B$12,0) -> 2 | H22: =ROUND(H19*INPUTS!$B$12,0) -> 2 | I22: =ROUND(I19*INPUTS!$B$12,0) -> 2 | ... M22: =ROUND(M19*INPUTS!$B$12,0) -> 2 | N22: =SUM(B22:M22) -> 17
A23: Elec End Inv | B23: =B19+B21-B8-B22 -> 192 | C23: =C19+C21-C8-C22 -> 319 | D23: =D19+D21-D8-D22 -> 472 | E23: =E19+E21-E8-E22 -> 674 | F23: =F19+F21-F8-F22 -> 824 | G23: =G19+G21-G8-G22 -> 988 | H23: =H19+H21-H8-H22 -> 1123 | I23: =I19+I21-I8-I22 -> 1168 | ... M23: =M19+M21-M8-M22 -> 1082
A24: Elec MOQ Alert | B24: =IF(AND(B21>0,B21<INPUTS!$B$143),"BELOW MOQ","") -> BELOW MOQ | C24: =IF(AND(C21>0,C21<INPUTS!$B$143),"BELOW MOQ","") -> BELOW MOQ | D24: =IF(AND(D21>0,D21<INPUTS!$B$143),"BELOW MOQ","") -> BELOW MOQ | E24: =IF(AND(E21>0,E21<INPUTS!$B$143),"BELOW MOQ","") -> BELOW MOQ | F24: =IF(AND(F21>0,F21<INPUTS!$B$143),"BELOW MOQ","") -> BELOW MOQ | G24: =IF(AND(G21>0,G21<INPUTS!$B$143),"BELOW MOQ","") -> BELOW MOQ | H24: =IF(AND(H21>0,H21<INPUTS!$B$143),"BELOW MOQ","") -> BELOW MOQ | I24: =IF(AND(I21>0,I21<INPUTS!$B$143),"BELOW MOQ","") -> BELOW MOQ | ... M24: =IF(AND(M21>0,M21<INPUTS!$B$143),"BELOW MOQ","") -> BELOW MOQ
A26: CHANNEL ALLOCATION & REVENUE (with ramp + cap enforced)
A27: — DTC (Website) — | B27: Active: | C27: =INPUTS!B41 -> Yes | D27: Ramp: | E27: =INPUTS!G41 -> 0 | F27: Max/mo: | G27: =INPUTS!H41 -> 30000
A28: Bar Units | B28: =IF(AND(INPUTS!$B$41="Yes",B$5>INPUTS!$G$41),IF(AND(INPUTS!$H$41>0,(ROUND(B$7*INPUTS!$C$41/$B$3,0)+ROUND(B$8*INPUTS!$C$41/$B$3,0))>INPUTS!$H$41),ROUND(ROUND(B$7*INPUTS!$C$41/$B$3,0)*INPUTS!$H$41/(ROUND(B$7*INPUTS!$C$41/$B$3,0)+ROUND(B$8*INPUTS!$C$41/$B$3,0)),0),ROUND(B$7*INPUTS!$C$41/$B$3,0)),0) -> 920 | C28: =IF(AND(INPUTS!$B$41="Yes",C$5>INPUTS!$G$41),IF(AND(INPUTS!$H$41>0,(ROUND(C$7*INPUTS!$C$41/$B$3,0)+ROUND(C$8*INPUTS!$C$41/$B$3,0))>INPUTS!$H$41),ROUND(ROUND(C$7*INPUTS!$C$41/$B$3,0)*INPUTS!$H$41/(ROUND(C$7*INPUTS!$C$41/$B$3,0)+ROUND(C$8*INPUTS!$C$41/$B$3,0)),0),ROUND(C$7*INPUTS!$C$41/$B$3,0)),0) -> 1320 | D28: =IF(AND(INPUTS!$B$41="Yes",D$5>INPUTS!$G$41),IF(AND(INPUTS!$H$41>0,(ROUND(D$7*INPUTS!$C$41/$B$3,0)+ROUND(D$8*INPUTS!$C$41/$B$3,0))>INPUTS!$H$41),ROUND(ROUND(D$7*INPUTS!$C$41/$B$3,0)*INPUTS!$H$41/(ROUND(D$7*INPUTS!$C$41/$B$3,0)+ROUND(D$8*INPUTS!$C$41/$B$3,0)),0),ROUND(D$7*INPUTS!$C$41/$B$3,0)),0) -> 1680 | E28: =IF(AND(INPUTS!$B$41="Yes",E$5>INPUTS!$G$41),IF(AND(INPUTS!$H$41>0,(ROUND(E$7*INPUTS!$C$41/$B$3,0)+ROUND(E$8*INPUTS!$C$41/$B$3,0))>INPUTS!$H$41),ROUND(ROUND(E$7*INPUTS!$C$41/$B$3,0)*INPUTS!$H$41/(ROUND(E$7*INPUTS!$C$41/$B$3,0)+ROUND(E$8*INPUTS!$C$41/$B$3,0)),0),ROUND(E$7*INPUTS!$C$41/$B$3,0)),0) -> 1900 | F28: =IF(AND(INPUTS!$B$41="Yes",F$5>INPUTS!$G$41),IF(AND(INPUTS!$H$41>0,(ROUND(F$7*INPUTS!$C$41/$B$3,0)+ROUND(F$8*INPUTS!$C$41/$B$3,0))>INPUTS!$H$41),ROUND(ROUND(F$7*INPUTS!$C$41/$B$3,0)*INPUTS!$H$41/(ROUND(F$7*INPUTS!$C$41/$B$3,0)+ROUND(F$8*INPUTS!$C$41/$B$3,0)),0),ROUND(F$7*INPUTS!$C$41/$B$3,0)),0) -> 1980 | G28: =IF(AND(INPUTS!$B$41="Yes",G$5>INPUTS!$G$41),IF(AND(INPUTS!$H$41>0,(ROUND(G$7*INPUTS!$C$41/$B$3,0)+ROUND(G$8*INPUTS!$C$41/$B$3,0))>INPUTS!$H$41),ROUND(ROUND(G$7*INPUTS!$C$41/$B$3,0)*INPUTS!$H$41/(ROUND(G$7*INPUTS!$C$41/$B$3,0)+ROUND(G$8*INPUTS!$C$41/$B$3,0)),0),ROUND(G$7*INPUTS!$C$41/$B$3,0)),0) -> 2280 | H28: =IF(AND(INPUTS!$B$41="Yes",H$5>INPUTS!$G$41),IF(AND(INPUTS!$H$41>0,(ROUND(H$7*INPUTS!$C$41/$B$3,0)+ROUND(H$8*INPUTS!$C$41/$B$3,0))>INPUTS!$H$41),ROUND(ROUND(H$7*INPUTS!$C$41/$B$3,0)*INPUTS!$H$41/(ROUND(H$7*INPUTS!$C$41/$B$3,0)+ROUND(H$8*INPUTS!$C$41/$B$3,0)),0),ROUND(H$7*INPUTS!$C$41/$B$3,0)),0) -> 2600 | I28: =IF(AND(INPUTS!$B$41="Yes",I$5>INPUTS!$G$41),IF(AND(INPUTS!$H$41>0,(ROUND(I$7*INPUTS!$C$41/$B$3,0)+ROUND(I$8*INPUTS!$C$41/$B$3,0))>INPUTS!$H$41),ROUND(ROUND(I$7*INPUTS!$C$41/$B$3,0)*INPUTS!$H$41/(ROUND(I$7*INPUTS!$C$41/$B$3,0)+ROUND(I$8*INPUTS!$C$41/$B$3,0)),0),ROUND(I$7*INPUTS!$C$41/$B$3,0)),0) -> 2800 | ... M28: =IF(AND(INPUTS!$B$41="Yes",M$5>INPUTS!$G$41),IF(AND(INPUTS!$H$41>0,(ROUND(M$7*INPUTS!$C$41/$B$3,0)+ROUND(M$8*INPUTS!$C$41/$B$3,0))>INPUTS!$H$41),ROUND(ROUND(M$7*INPUTS!$C$41/$B$3,0)*INPUTS!$H$41/(ROUND(M$7*INPUTS!$C$41/$B$3,0)+ROUND(M$8*INPUTS!$C$41/$B$3,0)),0),ROUND(M$7*INPUTS!$C$41/$B$3,0)),0) -> 3600 | N28: =SUM(B28:M28) -> 28370
A29: Elec Units | B29: =IF(AND(INPUTS!$B$41="Yes",B$5>INPUTS!$G$41),IF(AND(INPUTS!$H$41>0,(ROUND(B$7*INPUTS!$C$41/$B$3,0)+ROUND(B$8*INPUTS!$C$41/$B$3,0))>INPUTS!$H$41),ROUND(ROUND(B$8*INPUTS!$C$41/$B$3,0)*INPUTS!$H$41/(ROUND(B$7*INPUTS!$C$41/$B$3,0)+ROUND(B$8*INPUTS!$C$41/$B$3,0)),0),ROUND(B$8*INPUTS!$C$41/$B$3,0)),0) -> 510 | C29: =IF(AND(INPUTS!$B$41="Yes",C$5>INPUTS!$G$41),IF(AND(INPUTS!$H$41>0,(ROUND(C$7*INPUTS!$C$41/$B$3,0)+ROUND(C$8*INPUTS!$C$41/$B$3,0))>INPUTS!$H$41),ROUND(ROUND(C$8*INPUTS!$C$41/$B$3,0)*INPUTS!$H$41/(ROUND(C$7*INPUTS!$C$41/$B$3,0)+ROUND(C$8*INPUTS!$C$41/$B$3,0)),0),ROUND(C$8*INPUTS!$C$41/$B$3,0)),0) -> 850 | D29: =IF(AND(INPUTS!$B$41="Yes",D$5>INPUTS!$G$41),IF(AND(INPUTS!$H$41>0,(ROUND(D$7*INPUTS!$C$41/$B$3,0)+ROUND(D$8*INPUTS!$C$41/$B$3,0))>INPUTS!$H$41),ROUND(ROUND(D$8*INPUTS!$C$41/$B$3,0)*INPUTS!$H$41/(ROUND(D$7*INPUTS!$C$41/$B$3,0)+ROUND(D$8*INPUTS!$C$41/$B$3,0)),0),ROUND(D$8*INPUTS!$C$41/$B$3,0)),0) -> 1260 | E29: =IF(AND(INPUTS!$B$41="Yes",E$5>INPUTS!$G$41),IF(AND(INPUTS!$H$41>0,(ROUND(E$7*INPUTS!$C$41/$B$3,0)+ROUND(E$8*INPUTS!$C$41/$B$3,0))>INPUTS!$H$41),ROUND(ROUND(E$8*INPUTS!$C$41/$B$3,0)*INPUTS!$H$41/(ROUND(E$7*INPUTS!$C$41/$B$3,0)+ROUND(E$8*INPUTS!$C$41/$B$3,0)),0),ROUND(E$8*INPUTS!$C$41/$B$3,0)),0) -> 1800 | F29: =IF(AND(INPUTS!$B$41="Yes",F$5>INPUTS!$G$41),IF(AND(INPUTS!$H$41>0,(ROUND(F$7*INPUTS!$C$41/$B$3,0)+ROUND(F$8*INPUTS!$C$41/$B$3,0))>INPUTS!$H$41),ROUND(ROUND(F$8*INPUTS!$C$41/$B$3,0)*INPUTS!$H$41/(ROUND(F$7*INPUTS!$C$41/$B$3,0)+ROUND(F$8*INPUTS!$C$41/$B$3,0)),0),ROUND(F$8*INPUTS!$C$41/$B$3,0)),0) -> 2200 | G29: =IF(AND(INPUTS!$B$41="Yes",G$5>INPUTS!$G$41),IF(AND(INPUTS!$H$41>0,(ROUND(G$7*INPUTS!$C$41/$B$3,0)+ROUND(G$8*INPUTS!$C$41/$B$3,0))>INPUTS!$H$41),ROUND(ROUND(G$8*INPUTS!$C$41/$B$3,0)*INPUTS!$H$41/(ROUND(G$7*INPUTS!$C$41/$B$3,0)+ROUND(G$8*INPUTS!$C$41/$B$3,0)),0),ROUND(G$8*INPUTS!$C$41/$B$3,0)),0) -> 2640 | H29: =IF(AND(INPUTS!$B$41="Yes",H$5>INPUTS!$G$41),IF(AND(INPUTS!$H$41>0,(ROUND(H$7*INPUTS!$C$41/$B$3,0)+ROUND(H$8*INPUTS!$C$41/$B$3,0))>INPUTS!$H$41),ROUND(ROUND(H$8*INPUTS!$C$41/$B$3,0)*INPUTS!$H$41/(ROUND(H$7*INPUTS!$C$41/$B$3,0)+ROUND(H$8*INPUTS!$C$41/$B$3,0)),0),ROUND(H$8*INPUTS!$C$41/$B$3,0)),0) -> 3000 | I29: =IF(AND(INPUTS!$B$41="Yes",I$5>INPUTS!$G$41),IF(AND(INPUTS!$H$41>0,(ROUND(I$7*INPUTS!$C$41/$B$3,0)+ROUND(I$8*INPUTS!$C$41/$B$3,0))>INPUTS!$H$41),ROUND(ROUND(I$8*INPUTS!$C$41/$B$3,0)*INPUTS!$H$41/(ROUND(I$7*INPUTS!$C$41/$B$3,0)+ROUND(I$8*INPUTS!$C$41/$B$3,0)),0),ROUND(I$8*INPUTS!$C$41/$B$3,0)),0) -> 3120 | ... M29: =IF(AND(INPUTS!$B$41="Yes",M$5>INPUTS!$G$41),IF(AND(INPUTS!$H$41>0,(ROUND(M$7*INPUTS!$C$41/$B$3,0)+ROUND(M$8*INPUTS!$C$41/$B$3,0))>INPUTS!$H$41),ROUND(ROUND(M$8*INPUTS!$C$41/$B$3,0)*INPUTS!$H$41/(ROUND(M$7*INPUTS!$C$41/$B$3,0)+ROUND(M$8*INPUTS!$C$41/$B$3,0)),0),ROUND(M$8*INPUTS!$C$41/$B$3,0)),0) -> 2890 | N29: =SUM(B29:M29) -> 26630
A30: Revenue | B30: =B28*INPUTS!$D$41+B29*INPUTS!$E$41 -> 4367.5 | C30: =C28*INPUTS!$D$41+C29*INPUTS!$E$41 -> 6532.5 | D30: =D28*INPUTS!$D$41+D29*INPUTS!$E$41 -> 8715 | E30: =E28*INPUTS!$D$41+E29*INPUTS!$E$41 -> 10700 | F30: =F28*INPUTS!$D$41+F29*INPUTS!$E$41 -> 11880 | G30: =G28*INPUTS!$D$41+G29*INPUTS!$E$41 -> 13920 | H30: =H28*INPUTS!$D$41+H29*INPUTS!$E$41 -> 15850 | I30: =I28*INPUTS!$D$41+I29*INPUTS!$E$41 -> 16820 | ... M30: =M28*INPUTS!$D$41+M29*INPUTS!$E$41 -> 19102.5 | N30: =SUM(B30:M30) -> 159212.5
A31: Channel Costs | B31: =(B28+B29)*INPUTS!$F$41 -> 1215.5 | C31: =(C28+C29)*INPUTS!$F$41 -> 1844.5 | D31: =(D28+D29)*INPUTS!$F$41 -> 2499 | E31: =(E28+E29)*INPUTS!$F$41 -> 3145 | F31: =(F28+F29)*INPUTS!$F$41 -> 3553 | G31: =(G28+G29)*INPUTS!$F$41 -> 4182 | H31: =(H28+H29)*INPUTS!$F$41 -> 4760 | I31: =(I28+I29)*INPUTS!$F$41 -> 5032 | ... M31: =(M28+M29)*INPUTS!$F$41 -> 5516.5 | N31: =SUM(B31:M31) -> 46750
A33: — Amazon — | B33: Active: | C33: =INPUTS!B42 -> Yes | D33: Ramp: | E33: =INPUTS!G42 -> 2 | F33: Max/mo: | G33: =INPUTS!H42 -> 18000
A34: Bar Units | B34: =IF(AND(INPUTS!$B$42="Yes",B$5>INPUTS!$G$42),IF(AND(INPUTS!$H$42>0,(ROUND(B$7*INPUTS!$C$42/$B$3,0)+ROUND(B$8*INPUTS!$C$42/$B$3,0))>INPUTS!$H$42),ROUND(ROUND(B$7*INPUTS!$C$42/$B$3,0)*INPUTS!$H$42/(ROUND(B$7*INPUTS!$C$42/$B$3,0)+ROUND(B$8*INPUTS!$C$42/$B$3,0)),0),ROUND(B$7*INPUTS!$C$42/$B$3,0)),0) -> 0 | C34: =IF(AND(INPUTS!$B$42="Yes",C$5>INPUTS!$G$42),IF(AND(INPUTS!$H$42>0,(ROUND(C$7*INPUTS!$C$42/$B$3,0)+ROUND(C$8*INPUTS!$C$42/$B$3,0))>INPUTS!$H$42),ROUND(ROUND(C$7*INPUTS!$C$42/$B$3,0)*INPUTS!$H$42/(ROUND(C$7*INPUTS!$C$42/$B$3,0)+ROUND(C$8*INPUTS!$C$42/$B$3,0)),0),ROUND(C$7*INPUTS!$C$42/$B$3,0)),0) -> 0 | D34: =IF(AND(INPUTS!$B$42="Yes",D$5>INPUTS!$G$42),IF(AND(INPUTS!$H$42>0,(ROUND(D$7*INPUTS!$C$42/$B$3,0)+ROUND(D$8*INPUTS!$C$42/$B$3,0))>INPUTS!$H$42),ROUND(ROUND(D$7*INPUTS!$C$42/$B$3,0)*INPUTS!$H$42/(ROUND(D$7*INPUTS!$C$42/$B$3,0)+ROUND(D$8*INPUTS!$C$42/$B$3,0)),0),ROUND(D$7*INPUTS!$C$42/$B$3,0)),0) -> 840 | E34: =IF(AND(INPUTS!$B$42="Yes",E$5>INPUTS!$G$42),IF(AND(INPUTS!$H$42>0,(ROUND(E$7*INPUTS!$C$42/$B$3,0)+ROUND(E$8*INPUTS!$C$42/$B$3,0))>INPUTS!$H$42),ROUND(ROUND(E$7*INPUTS!$C$42/$B$3,0)*INPUTS!$H$42/(ROUND(E$7*INPUTS!$C$42/$B$3,0)+ROUND(E$8*INPUTS!$C$42/$B$3,0)),0),ROUND(E$7*INPUTS!$C$42/$B$3,0)),0) -> 950 | F34: =IF(AND(INPUTS!$B$42="Yes",F$5>INPUTS!$G$42),IF(AND(INPUTS!$H$42>0,(ROUND(F$7*INPUTS!$C$42/$B$3,0)+ROUND(F$8*INPUTS!$C$42/$B$3,0))>INPUTS!$H$42),ROUND(ROUND(F$7*INPUTS!$C$42/$B$3,0)*INPUTS!$H$42/(ROUND(F$7*INPUTS!$C$42/$B$3,0)+ROUND(F$8*INPUTS!$C$42/$B$3,0)),0),ROUND(F$7*INPUTS!$C$42/$B$3,0)),0) -> 990 | G34: =IF(AND(INPUTS!$B$42="Yes",G$5>INPUTS!$G$42),IF(AND(INPUTS!$H$42>0,(ROUND(G$7*INPUTS!$C$42/$B$3,0)+ROUND(G$8*INPUTS!$C$42/$B$3,0))>INPUTS!$H$42),ROUND(ROUND(G$7*INPUTS!$C$42/$B$3,0)*INPUTS!$H$42/(ROUND(G$7*INPUTS!$C$42/$B$3,0)+ROUND(G$8*INPUTS!$C$42/$B$3,0)),0),ROUND(G$7*INPUTS!$C$42/$B$3,0)),0) -> 1140 | H34: =IF(AND(INPUTS!$B$42="Yes",H$5>INPUTS!$G$42),IF(AND(INPUTS!$H$42>0,(ROUND(H$7*INPUTS!$C$42/$B$3,0)+ROUND(H$8*INPUTS!$C$42/$B$3,0))>INPUTS!$H$42),ROUND(ROUND(H$7*INPUTS!$C$42/$B$3,0)*INPUTS!$H$42/(ROUND(H$7*INPUTS!$C$42/$B$3,0)+ROUND(H$8*INPUTS!$C$42/$B$3,0)),0),ROUND(H$7*INPUTS!$C$42/$B$3,0)),0) -> 1300 | I34: =IF(AND(INPUTS!$B$42="Yes",I$5>INPUTS!$G$42),IF(AND(INPUTS!$H$42>0,(ROUND(I$7*INPUTS!$C$42/$B$3,0)+ROUND(I$8*INPUTS!$C$42/$B$3,0))>INPUTS!$H$42),ROUND(ROUND(I$7*INPUTS!$C$42/$B$3,0)*INPUTS!$H$42/(ROUND(I$7*INPUTS!$C$42/$B$3,0)+ROUND(I$8*INPUTS!$C$42/$B$3,0)),0),ROUND(I$7*INPUTS!$C$42/$B$3,0)),0) -> 1400 | ... M34: =IF(AND(INPUTS!$B$42="Yes",M$5>INPUTS!$G$42),IF(AND(INPUTS!$H$42>0,(ROUND(M$7*INPUTS!$C$42/$B$3,0)+ROUND(M$8*INPUTS!$C$42/$B$3,0))>INPUTS!$H$42),ROUND(ROUND(M$7*INPUTS!$C$42/$B$3,0)*INPUTS!$H$42/(ROUND(M$7*INPUTS!$C$42/$B$3,0)+ROUND(M$8*INPUTS!$C$42/$B$3,0)),0),ROUND(M$7*INPUTS!$C$42/$B$3,0)),0) -> 1800 | N34: =SUM(B34:M34) -> 13065
A35: Elec Units | B35: =IF(AND(INPUTS!$B$42="Yes",B$5>INPUTS!$G$42),IF(AND(INPUTS!$H$42>0,(ROUND(B$7*INPUTS!$C$42/$B$3,0)+ROUND(B$8*INPUTS!$C$42/$B$3,0))>INPUTS!$H$42),ROUND(ROUND(B$8*INPUTS!$C$42/$B$3,0)*INPUTS!$H$42/(ROUND(B$7*INPUTS!$C$42/$B$3,0)+ROUND(B$8*INPUTS!$C$42/$B$3,0)),0),ROUND(B$8*INPUTS!$C$42/$B$3,0)),0) -> 0 | C35: =IF(AND(INPUTS!$B$42="Yes",C$5>INPUTS!$G$42),IF(AND(INPUTS!$H$42>0,(ROUND(C$7*INPUTS!$C$42/$B$3,0)+ROUND(C$8*INPUTS!$C$42/$B$3,0))>INPUTS!$H$42),ROUND(ROUND(C$8*INPUTS!$C$42/$B$3,0)*INPUTS!$H$42/(ROUND(C$7*INPUTS!$C$42/$B$3,0)+ROUND(C$8*INPUTS!$C$42/$B$3,0)),0),ROUND(C$8*INPUTS!$C$42/$B$3,0)),0) -> 0 | D35: =IF(AND(INPUTS!$B$42="Yes",D$5>INPUTS!$G$42),IF(AND(INPUTS!$H$42>0,(ROUND(D$7*INPUTS!$C$42/$B$3,0)+ROUND(D$8*INPUTS!$C$42/$B$3,0))>INPUTS!$H$42),ROUND(ROUND(D$8*INPUTS!$C$42/$B$3,0)*INPUTS!$H$42/(ROUND(D$7*INPUTS!$C$42/$B$3,0)+ROUND(D$8*INPUTS!$C$42/$B$3,0)),0),ROUND(D$8*INPUTS!$C$42/$B$3,0)),0) -> 630 | E35: =IF(AND(INPUTS!$B$42="Yes",E$5>INPUTS!$G$42),IF(AND(INPUTS!$H$42>0,(ROUND(E$7*INPUTS!$C$42/$B$3,0)+ROUND(E$8*INPUTS!$C$42/$B$3,0))>INPUTS!$H$42),ROUND(ROUND(E$8*INPUTS!$C$42/$B$3,0)*INPUTS!$H$42/(ROUND(E$7*INPUTS!$C$42/$B$3,0)+ROUND(E$8*INPUTS!$C$42/$B$3,0)),0),ROUND(E$8*INPUTS!$C$42/$B$3,0)),0) -> 900 | F35: =IF(AND(INPUTS!$B$42="Yes",F$5>INPUTS!$G$42),IF(AND(INPUTS!$H$42>0,(ROUND(F$7*INPUTS!$C$42/$B$3,0)+ROUND(F$8*INPUTS!$C$42/$B$3,0))>INPUTS!$H$42),ROUND(ROUND(F$8*INPUTS!$C$42/$B$3,0)*INPUTS!$H$42/(ROUND(F$7*INPUTS!$C$42/$B$3,0)+ROUND(F$8*INPUTS!$C$42/$B$3,0)),0),ROUND(F$8*INPUTS!$C$42/$B$3,0)),0) -> 1100 | G35: =IF(AND(INPUTS!$B$42="Yes",G$5>INPUTS!$G$42),IF(AND(INPUTS!$H$42>0,(ROUND(G$7*INPUTS!$C$42/$B$3,0)+ROUND(G$8*INPUTS!$C$42/$B$3,0))>INPUTS!$H$42),ROUND(ROUND(G$8*INPUTS!$C$42/$B$3,0)*INPUTS!$H$42/(ROUND(G$7*INPUTS!$C$42/$B$3,0)+ROUND(G$8*INPUTS!$C$42/$B$3,0)),0),ROUND(G$8*INPUTS!$C$42/$B$3,0)),0) -> 1320 | H35: =IF(AND(INPUTS!$B$42="Yes",H$5>INPUTS!$G$42),IF(AND(INPUTS!$H$42>0,(ROUND(H$7*INPUTS!$C$42/$B$3,0)+ROUND(H$8*INPUTS!$C$42/$B$3,0))>INPUTS!$H$42),ROUND(ROUND(H$8*INPUTS!$C$42/$B$3,0)*INPUTS!$H$42/(ROUND(H$7*INPUTS!$C$42/$B$3,0)+ROUND(H$8*INPUTS!$C$42/$B$3,0)),0),ROUND(H$8*INPUTS!$C$42/$B$3,0)),0) -> 1500 | I35: =IF(AND(INPUTS!$B$42="Yes",I$5>INPUTS!$G$42),IF(AND(INPUTS!$H$42>0,(ROUND(I$7*INPUTS!$C$42/$B$3,0)+ROUND(I$8*INPUTS!$C$42/$B$3,0))>INPUTS!$H$42),ROUND(ROUND(I$8*INPUTS!$C$42/$B$3,0)*INPUTS!$H$42/(ROUND(I$7*INPUTS!$C$42/$B$3,0)+ROUND(I$8*INPUTS!$C$42/$B$3,0)),0),ROUND(I$8*INPUTS!$C$42/$B$3,0)),0) -> 1560 | ... M35: =IF(AND(INPUTS!$B$42="Yes",M$5>INPUTS!$G$42),IF(AND(INPUTS!$H$42>0,(ROUND(M$7*INPUTS!$C$42/$B$3,0)+ROUND(M$8*INPUTS!$C$42/$B$3,0))>INPUTS!$H$42),ROUND(ROUND(M$8*INPUTS!$C$42/$B$3,0)*INPUTS!$H$42/(ROUND(M$7*INPUTS!$C$42/$B$3,0)+ROUND(M$8*INPUTS!$C$42/$B$3,0)),0),ROUND(M$8*INPUTS!$C$42/$B$3,0)),0) -> 1445 | N35: =SUM(B35:M35) -> 12635
A36: Revenue | B36: =B34*INPUTS!$D$42+B35*INPUTS!$E$42 -> 0 | C36: =C34*INPUTS!$D$42+C35*INPUTS!$E$42 -> 0 | D36: =D34*INPUTS!$D$42+D35*INPUTS!$E$42 -> 3486 | E36: =E34*INPUTS!$D$42+E35*INPUTS!$E$42 -> 4280 | F36: =F34*INPUTS!$D$42+F35*INPUTS!$E$42 -> 4752 | G36: =G34*INPUTS!$D$42+G35*INPUTS!$E$42 -> 5568 | H36: =H34*INPUTS!$D$42+H35*INPUTS!$E$42 -> 6340 | I36: =I34*INPUTS!$D$42+I35*INPUTS!$E$42 -> 6728 | ... M36: =M34*INPUTS!$D$42+M35*INPUTS!$E$42 -> 7641 | N36: =SUM(B36:M36) -> 59325
A37: Channel Costs | B37: =(B34+B35)*INPUTS!$F$42 -> 0 | C37: =(C34+C35)*INPUTS!$F$42 -> 0 | D37: =(D34+D35)*INPUTS!$F$42 -> 808.5 | E37: =(E34+E35)*INPUTS!$F$42 -> 1017.5 | F37: =(F34+F35)*INPUTS!$F$42 -> 1149.5 | G37: =(G34+G35)*INPUTS!$F$42 -> 1353 | H37: =(H34+H35)*INPUTS!$F$42 -> 1540 | I37: =(I34+I35)*INPUTS!$F$42 -> 1628 | ... M37: =(M34+M35)*INPUTS!$F$42 -> 1784.75 | N37: =SUM(B37:M37) -> 14135
A39: — Big Box Retail — | B39: Active: | C39: =INPUTS!B43 -> No | D39: Ramp: | E39: =INPUTS!G43 -> 24 | F39: Max/mo: | G39: =INPUTS!H43 -> 40000
A40: Bar Units | B40: =IF(AND(INPUTS!$B$43="Yes",B$5>INPUTS!$G$43),IF(AND(INPUTS!$H$43>0,(ROUND(B$7*INPUTS!$C$43/$B$3,0)+ROUND(B$8*INPUTS!$C$43/$B$3,0))>INPUTS!$H$43),ROUND(ROUND(B$7*INPUTS!$C$43/$B$3,0)*INPUTS!$H$43/(ROUND(B$7*INPUTS!$C$43/$B$3,0)+ROUND(B$8*INPUTS!$C$43/$B$3,0)),0),ROUND(B$7*INPUTS!$C$43/$B$3,0)),0) -> 0 | C40: =IF(AND(INPUTS!$B$43="Yes",C$5>INPUTS!$G$43),IF(AND(INPUTS!$H$43>0,(ROUND(C$7*INPUTS!$C$43/$B$3,0)+ROUND(C$8*INPUTS!$C$43/$B$3,0))>INPUTS!$H$43),ROUND(ROUND(C$7*INPUTS!$C$43/$B$3,0)*INPUTS!$H$43/(ROUND(C$7*INPUTS!$C$43/$B$3,0)+ROUND(C$8*INPUTS!$C$43/$B$3,0)),0),ROUND(C$7*INPUTS!$C$43/$B$3,0)),0) -> 0 | D40: =IF(AND(INPUTS!$B$43="Yes",D$5>INPUTS!$G$43),IF(AND(INPUTS!$H$43>0,(ROUND(D$7*INPUTS!$C$43/$B$3,0)+ROUND(D$8*INPUTS!$C$43/$B$3,0))>INPUTS!$H$43),ROUND(ROUND(D$7*INPUTS!$C$43/$B$3,0)*INPUTS!$H$43/(ROUND(D$7*INPUTS!$C$43/$B$3,0)+ROUND(D$8*INPUTS!$C$43/$B$3,0)),0),ROUND(D$7*INPUTS!$C$43/$B$3,0)),0) -> 0 | E40: =IF(AND(INPUTS!$B$43="Yes",E$5>INPUTS!$G$43),IF(AND(INPUTS!$H$43>0,(ROUND(E$7*INPUTS!$C$43/$B$3,0)+ROUND(E$8*INPUTS!$C$43/$B$3,0))>INPUTS!$H$43),ROUND(ROUND(E$7*INPUTS!$C$43/$B$3,0)*INPUTS!$H$43/(ROUND(E$7*INPUTS!$C$43/$B$3,0)+ROUND(E$8*INPUTS!$C$43/$B$3,0)),0),ROUND(E$7*INPUTS!$C$43/$B$3,0)),0) -> 0 | F40: =IF(AND(INPUTS!$B$43="Yes",F$5>INPUTS!$G$43),IF(AND(INPUTS!$H$43>0,(ROUND(F$7*INPUTS!$C$43/$B$3,0)+ROUND(F$8*INPUTS!$C$43/$B$3,0))>INPUTS!$H$43),ROUND(ROUND(F$7*INPUTS!$C$43/$B$3,0)*INPUTS!$H$43/(ROUND(F$7*INPUTS!$C$43/$B$3,0)+ROUND(F$8*INPUTS!$C$43/$B$3,0)),0),ROUND(F$7*INPUTS!$C$43/$B$3,0)),0) -> 0 | G40: =IF(AND(INPUTS!$B$43="Yes",G$5>INPUTS!$G$43),IF(AND(INPUTS!$H$43>0,(ROUND(G$7*INPUTS!$C$43/$B$3,0)+ROUND(G$8*INPUTS!$C$43/$B$3,0))>INPUTS!$H$43),ROUND(ROUND(G$7*INPUTS!$C$43/$B$3,0)*INPUTS!$H$43/(ROUND(G$7*INPUTS!$C$43/$B$3,0)+ROUND(G$8*INPUTS!$C$43/$B$3,0)),0),ROUND(G$7*INPUTS!$C$43/$B$3,0)),0) -> 0 | H40: =IF(AND(INPUTS!$B$43="Yes",H$5>INPUTS!$G$43),IF(AND(INPUTS!$H$43>0,(ROUND(H$7*INPUTS!$C$43/$B$3,0)+ROUND(H$8*INPUTS!$C$43/$B$3,0))>INPUTS!$H$43),ROUND(ROUND(H$7*INPUTS!$C$43/$B$3,0)*INPUTS!$H$43/(ROUND(H$7*INPUTS!$C$43/$B$3,0)+ROUND(H$8*INPUTS!$C$43/$B$3,0)),0),ROUND(H$7*INPUTS!$C$43/$B$3,0)),0) -> 0 | I40: =IF(AND(INPUTS!$B$43="Yes",I$5>INPUTS!$G$43),IF(AND(INPUTS!$H$43>0,(ROUND(I$7*INPUTS!$C$43/$B$3,0)+ROUND(I$8*INPUTS!$C$43/$B$3,0))>INPUTS!$H$43),ROUND(ROUND(I$7*INPUTS!$C$43/$B$3,0)*INPUTS!$H$43/(ROUND(I$7*INPUTS!$C$43/$B$3,0)+ROUND(I$8*INPUTS!$C$43/$B$3,0)),0),ROUND(I$7*INPUTS!$C$43/$B$3,0)),0) -> 0 | ... M40: =IF(AND(INPUTS!$B$43="Yes",M$5>INPUTS!$G$43),IF(AND(INPUTS!$H$43>0,(ROUND(M$7*INPUTS!$C$43/$B$3,0)+ROUND(M$8*INPUTS!$C$43/$B$3,0))>INPUTS!$H$43),ROUND(ROUND(M$7*INPUTS!$C$43/$B$3,0)*INPUTS!$H$43/(ROUND(M$7*INPUTS!$C$43/$B$3,0)+ROUND(M$8*INPUTS!$C$43/$B$3,0)),0),ROUND(M$7*INPUTS!$C$43/$B$3,0)),0) -> 0 | N40: =SUM(B40:M40) -> 0
A41: Elec Units | B41: =IF(AND(INPUTS!$B$43="Yes",B$5>INPUTS!$G$43),IF(AND(INPUTS!$H$43>0,(ROUND(B$7*INPUTS!$C$43/$B$3,0)+ROUND(B$8*INPUTS!$C$43/$B$3,0))>INPUTS!$H$43),ROUND(ROUND(B$8*INPUTS!$C$43/$B$3,0)*INPUTS!$H$43/(ROUND(B$7*INPUTS!$C$43/$B$3,0)+ROUND(B$8*INPUTS!$C$43/$B$3,0)),0),ROUND(B$8*INPUTS!$C$43/$B$3,0)),0) -> 0 | C41: =IF(AND(INPUTS!$B$43="Yes",C$5>INPUTS!$G$43),IF(AND(INPUTS!$H$43>0,(ROUND(C$7*INPUTS!$C$43/$B$3,0)+ROUND(C$8*INPUTS!$C$43/$B$3,0))>INPUTS!$H$43),ROUND(ROUND(C$8*INPUTS!$C$43/$B$3,0)*INPUTS!$H$43/(ROUND(C$7*INPUTS!$C$43/$B$3,0)+ROUND(C$8*INPUTS!$C$43/$B$3,0)),0),ROUND(C$8*INPUTS!$C$43/$B$3,0)),0) -> 0 | D41: =IF(AND(INPUTS!$B$43="Yes",D$5>INPUTS!$G$43),IF(AND(INPUTS!$H$43>0,(ROUND(D$7*INPUTS!$C$43/$B$3,0)+ROUND(D$8*INPUTS!$C$43/$B$3,0))>INPUTS!$H$43),ROUND(ROUND(D$8*INPUTS!$C$43/$B$3,0)*INPUTS!$H$43/(ROUND(D$7*INPUTS!$C$43/$B$3,0)+ROUND(D$8*INPUTS!$C$43/$B$3,0)),0),ROUND(D$8*INPUTS!$C$43/$B$3,0)),0) -> 0 | E41: =IF(AND(INPUTS!$B$43="Yes",E$5>INPUTS!$G$43),IF(AND(INPUTS!$H$43>0,(ROUND(E$7*INPUTS!$C$43/$B$3,0)+ROUND(E$8*INPUTS!$C$43/$B$3,0))>INPUTS!$H$43),ROUND(ROUND(E$8*INPUTS!$C$43/$B$3,0)*INPUTS!$H$43/(ROUND(E$7*INPUTS!$C$43/$B$3,0)+ROUND(E$8*INPUTS!$C$43/$B$3,0)),0),ROUND(E$8*INPUTS!$C$43/$B$3,0)),0) -> 0 | F41: =IF(AND(INPUTS!$B$43="Yes",F$5>INPUTS!$G$43),IF(AND(INPUTS!$H$43>0,(ROUND(F$7*INPUTS!$C$43/$B$3,0)+ROUND(F$8*INPUTS!$C$43/$B$3,0))>INPUTS!$H$43),ROUND(ROUND(F$8*INPUTS!$C$43/$B$3,0)*INPUTS!$H$43/(ROUND(F$7*INPUTS!$C$43/$B$3,0)+ROUND(F$8*INPUTS!$C$43/$B$3,0)),0),ROUND(F$8*INPUTS!$C$43/$B$3,0)),0) -> 0 | G41: =IF(AND(INPUTS!$B$43="Yes",G$5>INPUTS!$G$43),IF(AND(INPUTS!$H$43>0,(ROUND(G$7*INPUTS!$C$43/$B$3,0)+ROUND(G$8*INPUTS!$C$43/$B$3,0))>INPUTS!$H$43),ROUND(ROUND(G$8*INPUTS!$C$43/$B$3,0)*INPUTS!$H$43/(ROUND(G$7*INPUTS!$C$43/$B$3,0)+ROUND(G$8*INPUTS!$C$43/$B$3,0)),0),ROUND(G$8*INPUTS!$C$43/$B$3,0)),0) -> 0 | H41: =IF(AND(INPUTS!$B$43="Yes",H$5>INPUTS!$G$43),IF(AND(INPUTS!$H$43>0,(ROUND(H$7*INPUTS!$C$43/$B$3,0)+ROUND(H$8*INPUTS!$C$43/$B$3,0))>INPUTS!$H$43),ROUND(ROUND(H$8*INPUTS!$C$43/$B$3,0)*INPUTS!$H$43/(ROUND(H$7*INPUTS!$C$43/$B$3,0)+ROUND(H$8*INPUTS!$C$43/$B$3,0)),0),ROUND(H$8*INPUTS!$C$43/$B$3,0)),0) -> 0 | I41: =IF(AND(INPUTS!$B$43="Yes",I$5>INPUTS!$G$43),IF(AND(INPUTS!$H$43>0,(ROUND(I$7*INPUTS!$C$43/$B$3,0)+ROUND(I$8*INPUTS!$C$43/$B$3,0))>INPUTS!$H$43),ROUND(ROUND(I$8*INPUTS!$C$43/$B$3,0)*INPUTS!$H$43/(ROUND(I$7*INPUTS!$C$43/$B$3,0)+ROUND(I$8*INPUTS!$C$43/$B$3,0)),0),ROUND(I$8*INPUTS!$C$43/$B$3,0)),0) -> 0 | ... M41: =IF(AND(INPUTS!$B$43="Yes",M$5>INPUTS!$G$43),IF(AND(INPUTS!$H$43>0,(ROUND(M$7*INPUTS!$C$43/$B$3,0)+ROUND(M$8*INPUTS!$C$43/$B$3,0))>INPUTS!$H$43),ROUND(ROUND(M$8*INPUTS!$C$43/$B$3,0)*INPUTS!$H$43/(ROUND(M$7*INPUTS!$C$43/$B$3,0)+ROUND(M$8*INPUTS!$C$43/$B$3,0)),0),ROUND(M$8*INPUTS!$C$43/$B$3,0)),0) -> 0 | N41: =SUM(B41:M41) -> 0
A42: Revenue | B42: =B40*INPUTS!$D$43+B41*INPUTS!$E$43 -> 0 | C42: =C40*INPUTS!$D$43+C41*INPUTS!$E$43 -> 0 | D42: =D40*INPUTS!$D$43+D41*INPUTS!$E$43 -> 0 | E42: =E40*INPUTS!$D$43+E41*INPUTS!$E$43 -> 0 | F42: =F40*INPUTS!$D$43+F41*INPUTS!$E$43 -> 0 | G42: =G40*INPUTS!$D$43+G41*INPUTS!$E$43 -> 0 | H42: =H40*INPUTS!$D$43+H41*INPUTS!$E$43 -> 0 | I42: =I40*INPUTS!$D$43+I41*INPUTS!$E$43 -> 0 | ... M42: =M40*INPUTS!$D$43+M41*INPUTS!$E$43 -> 0 | N42: =SUM(B42:M42) -> 0
A43: Channel Costs | B43: =(B40+B41)*INPUTS!$F$43 -> 0 | C43: =(C40+C41)*INPUTS!$F$43 -> 0 | D43: =(D40+D41)*INPUTS!$F$43 -> 0 | E43: =(E40+E41)*INPUTS!$F$43 -> 0 | F43: =(F40+F41)*INPUTS!$F$43 -> 0 | G43: =(G40+G41)*INPUTS!$F$43 -> 0 | H43: =(H40+H41)*INPUTS!$F$43 -> 0 | I43: =(I40+I41)*INPUTS!$F$43 -> 0 | ... M43: =(M40+M41)*INPUTS!$F$43 -> 0 | N43: =SUM(B43:M43) -> 0
A45: — Natural/Specialty — | B45: Active: | C45: =INPUTS!B44 -> Yes | D45: Ramp: | E45: =INPUTS!G44 -> 4 | F45: Max/mo: | G45: =INPUTS!H44 -> 9000
A46: Bar Units | B46: =IF(AND(INPUTS!$B$44="Yes",B$5>INPUTS!$G$44),IF(AND(INPUTS!$H$44>0,(ROUND(B$7*INPUTS!$C$44/$B$3,0)+ROUND(B$8*INPUTS!$C$44/$B$3,0))>INPUTS!$H$44),ROUND(ROUND(B$7*INPUTS!$C$44/$B$3,0)*INPUTS!$H$44/(ROUND(B$7*INPUTS!$C$44/$B$3,0)+ROUND(B$8*INPUTS!$C$44/$B$3,0)),0),ROUND(B$7*INPUTS!$C$44/$B$3,0)),0) -> 0 | C46: =IF(AND(INPUTS!$B$44="Yes",C$5>INPUTS!$G$44),IF(AND(INPUTS!$H$44>0,(ROUND(C$7*INPUTS!$C$44/$B$3,0)+ROUND(C$8*INPUTS!$C$44/$B$3,0))>INPUTS!$H$44),ROUND(ROUND(C$7*INPUTS!$C$44/$B$3,0)*INPUTS!$H$44/(ROUND(C$7*INPUTS!$C$44/$B$3,0)+ROUND(C$8*INPUTS!$C$44/$B$3,0)),0),ROUND(C$7*INPUTS!$C$44/$B$3,0)),0) -> 0 | D46: =IF(AND(INPUTS!$B$44="Yes",D$5>INPUTS!$G$44),IF(AND(INPUTS!$H$44>0,(ROUND(D$7*INPUTS!$C$44/$B$3,0)+ROUND(D$8*INPUTS!$C$44/$B$3,0))>INPUTS!$H$44),ROUND(ROUND(D$7*INPUTS!$C$44/$B$3,0)*INPUTS!$H$44/(ROUND(D$7*INPUTS!$C$44/$B$3,0)+ROUND(D$8*INPUTS!$C$44/$B$3,0)),0),ROUND(D$7*INPUTS!$C$44/$B$3,0)),0) -> 0 | E46: =IF(AND(INPUTS!$B$44="Yes",E$5>INPUTS!$G$44),IF(AND(INPUTS!$H$44>0,(ROUND(E$7*INPUTS!$C$44/$B$3,0)+ROUND(E$8*INPUTS!$C$44/$B$3,0))>INPUTS!$H$44),ROUND(ROUND(E$7*INPUTS!$C$44/$B$3,0)*INPUTS!$H$44/(ROUND(E$7*INPUTS!$C$44/$B$3,0)+ROUND(E$8*INPUTS!$C$44/$B$3,0)),0),ROUND(E$7*INPUTS!$C$44/$B$3,0)),0) -> 0 | F46: =IF(AND(INPUTS!$B$44="Yes",F$5>INPUTS!$G$44),IF(AND(INPUTS!$H$44>0,(ROUND(F$7*INPUTS!$C$44/$B$3,0)+ROUND(F$8*INPUTS!$C$44/$B$3,0))>INPUTS!$H$44),ROUND(ROUND(F$7*INPUTS!$C$44/$B$3,0)*INPUTS!$H$44/(ROUND(F$7*INPUTS!$C$44/$B$3,0)+ROUND(F$8*INPUTS!$C$44/$B$3,0)),0),ROUND(F$7*INPUTS!$C$44/$B$3,0)),0) -> 743 | G46: =IF(AND(INPUTS!$B$44="Yes",G$5>INPUTS!$G$44),IF(AND(INPUTS!$H$44>0,(ROUND(G$7*INPUTS!$C$44/$B$3,0)+ROUND(G$8*INPUTS!$C$44/$B$3,0))>INPUTS!$H$44),ROUND(ROUND(G$7*INPUTS!$C$44/$B$3,0)*INPUTS!$H$44/(ROUND(G$7*INPUTS!$C$44/$B$3,0)+ROUND(G$8*INPUTS!$C$44/$B$3,0)),0),ROUND(G$7*INPUTS!$C$44/$B$3,0)),0) -> 855 | H46: =IF(AND(INPUTS!$B$44="Yes",H$5>INPUTS!$G$44),IF(AND(INPUTS!$H$44>0,(ROUND(H$7*INPUTS!$C$44/$B$3,0)+ROUND(H$8*INPUTS!$C$44/$B$3,0))>INPUTS!$H$44),ROUND(ROUND(H$7*INPUTS!$C$44/$B$3,0)*INPUTS!$H$44/(ROUND(H$7*INPUTS!$C$44/$B$3,0)+ROUND(H$8*INPUTS!$C$44/$B$3,0)),0),ROUND(H$7*INPUTS!$C$44/$B$3,0)),0) -> 975 | I46: =IF(AND(INPUTS!$B$44="Yes",I$5>INPUTS!$G$44),IF(AND(INPUTS!$H$44>0,(ROUND(I$7*INPUTS!$C$44/$B$3,0)+ROUND(I$8*INPUTS!$C$44/$B$3,0))>INPUTS!$H$44),ROUND(ROUND(I$7*INPUTS!$C$44/$B$3,0)*INPUTS!$H$44/(ROUND(I$7*INPUTS!$C$44/$B$3,0)+ROUND(I$8*INPUTS!$C$44/$B$3,0)),0),ROUND(I$7*INPUTS!$C$44/$B$3,0)),0) -> 1050 | ... M46: =IF(AND(INPUTS!$B$44="Yes",M$5>INPUTS!$G$44),IF(AND(INPUTS!$H$44>0,(ROUND(M$7*INPUTS!$C$44/$B$3,0)+ROUND(M$8*INPUTS!$C$44/$B$3,0))>INPUTS!$H$44),ROUND(ROUND(M$7*INPUTS!$C$44/$B$3,0)*INPUTS!$H$44/(ROUND(M$7*INPUTS!$C$44/$B$3,0)+ROUND(M$8*INPUTS!$C$44/$B$3,0)),0),ROUND(M$7*INPUTS!$C$44/$B$3,0)),0) -> 1350 | N46: =SUM(B46:M46) -> 8457
A47: Elec Units | B47: =IF(AND(INPUTS!$B$44="Yes",B$5>INPUTS!$G$44),IF(AND(INPUTS!$H$44>0,(ROUND(B$7*INPUTS!$C$44/$B$3,0)+ROUND(B$8*INPUTS!$C$44/$B$3,0))>INPUTS!$H$44),ROUND(ROUND(B$8*INPUTS!$C$44/$B$3,0)*INPUTS!$H$44/(ROUND(B$7*INPUTS!$C$44/$B$3,0)+ROUND(B$8*INPUTS!$C$44/$B$3,0)),0),ROUND(B$8*INPUTS!$C$44/$B$3,0)),0) -> 0 | C47: =IF(AND(INPUTS!$B$44="Yes",C$5>INPUTS!$G$44),IF(AND(INPUTS!$H$44>0,(ROUND(C$7*INPUTS!$C$44/$B$3,0)+ROUND(C$8*INPUTS!$C$44/$B$3,0))>INPUTS!$H$44),ROUND(ROUND(C$8*INPUTS!$C$44/$B$3,0)*INPUTS!$H$44/(ROUND(C$7*INPUTS!$C$44/$B$3,0)+ROUND(C$8*INPUTS!$C$44/$B$3,0)),0),ROUND(C$8*INPUTS!$C$44/$B$3,0)),0) -> 0 | D47: =IF(AND(INPUTS!$B$44="Yes",D$5>INPUTS!$G$44),IF(AND(INPUTS!$H$44>0,(ROUND(D$7*INPUTS!$C$44/$B$3,0)+ROUND(D$8*INPUTS!$C$44/$B$3,0))>INPUTS!$H$44),ROUND(ROUND(D$8*INPUTS!$C$44/$B$3,0)*INPUTS!$H$44/(ROUND(D$7*INPUTS!$C$44/$B$3,0)+ROUND(D$8*INPUTS!$C$44/$B$3,0)),0),ROUND(D$8*INPUTS!$C$44/$B$3,0)),0) -> 0 | E47: =IF(AND(INPUTS!$B$44="Yes",E$5>INPUTS!$G$44),IF(AND(INPUTS!$H$44>0,(ROUND(E$7*INPUTS!$C$44/$B$3,0)+ROUND(E$8*INPUTS!$C$44/$B$3,0))>INPUTS!$H$44),ROUND(ROUND(E$8*INPUTS!$C$44/$B$3,0)*INPUTS!$H$44/(ROUND(E$7*INPUTS!$C$44/$B$3,0)+ROUND(E$8*INPUTS!$C$44/$B$3,0)),0),ROUND(E$8*INPUTS!$C$44/$B$3,0)),0) -> 0 | F47: =IF(AND(INPUTS!$B$44="Yes",F$5>INPUTS!$G$44),IF(AND(INPUTS!$H$44>0,(ROUND(F$7*INPUTS!$C$44/$B$3,0)+ROUND(F$8*INPUTS!$C$44/$B$3,0))>INPUTS!$H$44),ROUND(ROUND(F$8*INPUTS!$C$44/$B$3,0)*INPUTS!$H$44/(ROUND(F$7*INPUTS!$C$44/$B$3,0)+ROUND(F$8*INPUTS!$C$44/$B$3,0)),0),ROUND(F$8*INPUTS!$C$44/$B$3,0)),0) -> 825 | G47: =IF(AND(INPUTS!$B$44="Yes",G$5>INPUTS!$G$44),IF(AND(INPUTS!$H$44>0,(ROUND(G$7*INPUTS!$C$44/$B$3,0)+ROUND(G$8*INPUTS!$C$44/$B$3,0))>INPUTS!$H$44),ROUND(ROUND(G$8*INPUTS!$C$44/$B$3,0)*INPUTS!$H$44/(ROUND(G$7*INPUTS!$C$44/$B$3,0)+ROUND(G$8*INPUTS!$C$44/$B$3,0)),0),ROUND(G$8*INPUTS!$C$44/$B$3,0)),0) -> 990 | H47: =IF(AND(INPUTS!$B$44="Yes",H$5>INPUTS!$G$44),IF(AND(INPUTS!$H$44>0,(ROUND(H$7*INPUTS!$C$44/$B$3,0)+ROUND(H$8*INPUTS!$C$44/$B$3,0))>INPUTS!$H$44),ROUND(ROUND(H$8*INPUTS!$C$44/$B$3,0)*INPUTS!$H$44/(ROUND(H$7*INPUTS!$C$44/$B$3,0)+ROUND(H$8*INPUTS!$C$44/$B$3,0)),0),ROUND(H$8*INPUTS!$C$44/$B$3,0)),0) -> 1125 | I47: =IF(AND(INPUTS!$B$44="Yes",I$5>INPUTS!$G$44),IF(AND(INPUTS!$H$44>0,(ROUND(I$7*INPUTS!$C$44/$B$3,0)+ROUND(I$8*INPUTS!$C$44/$B$3,0))>INPUTS!$H$44),ROUND(ROUND(I$8*INPUTS!$C$44/$B$3,0)*INPUTS!$H$44/(ROUND(I$7*INPUTS!$C$44/$B$3,0)+ROUND(I$8*INPUTS!$C$44/$B$3,0)),0),ROUND(I$8*INPUTS!$C$44/$B$3,0)),0) -> 1170 | ... M47: =IF(AND(INPUTS!$B$44="Yes",M$5>INPUTS!$G$44),IF(AND(INPUTS!$H$44>0,(ROUND(M$7*INPUTS!$C$44/$B$3,0)+ROUND(M$8*INPUTS!$C$44/$B$3,0))>INPUTS!$H$44),ROUND(ROUND(M$8*INPUTS!$C$44/$B$3,0)*INPUTS!$H$44/(ROUND(M$7*INPUTS!$C$44/$B$3,0)+ROUND(M$8*INPUTS!$C$44/$B$3,0)),0),ROUND(M$8*INPUTS!$C$44/$B$3,0)),0) -> 1084 | N47: =SUM(B47:M47) -> 8330
...

Sheet CALC_PL
A1: CALC_PL — 5-Year P&L (Bars + Ingredient Licensing)
A2: Mirrors model.js lines 144-226. Uses v3.0 ORIGINAL bar/elec COGS (col I on CALC_COGS) so this P&L reproduces the deck. Corrected COGS (col K on CALC_COGS, no overhead double-count) gives ~$30-50K higher EBITDA/yr at scale — shown in AUDIT (Pass 3). Bars revenue ignores channel ramp+cap (per model.js); use CALC_MONTHLY Y1 Total for ramp-aware Y1 revenue.
A5: Line Item | B5: Year 1 | C5: Year 2 | D5: Year 3 | E5: Year 4 | F5: Year 5 | G5: 5-Yr Total
A6: Cumulative Growth Factor | B6: 1 | C6: =B6*(1+INPUTS!$C$61) -> 2.5 | D6: =C6*(1+INPUTS!$D$61) -> 5 | E6: =D6*(1+INPUTS!$E$61) -> 8.35 | F6: =E6*(1+INPUTS!$F$61) -> 13.36
A7: Bar Units | B7: =CALC_MONTHLY!N7 -> 70925 | C7: =ROUND($B$7*C6,0) -> 177313 | D7: =ROUND($B$7*D6,0) -> 354625 | E7: =ROUND($B$7*E6,0) -> 592224 | F7: =ROUND($B$7*F6,0) -> 947558 | G7: =SUM(B7:F7) -> 2142645
A8: Elec Units | B8: =CALC_MONTHLY!N8 -> 66575 | C8: =ROUND($B$8*C6,0) -> 166438 | D8: =ROUND($B$8*D6,0) -> 332875 | E8: =ROUND($B$8*E6,0) -> 555901 | F8: =ROUND($B$8*F6,0) -> 889442 | G8: =SUM(B8:F8) -> 2011231
A9: Total Units | B9: =B7+B8 -> 137500 | C9: =C7+C8 -> 343751 | D9: =D7+D8 -> 687500 | E9: =E7+E8 -> 1148125 | F9: =F7+F8 -> 1837000 | G9: =SUM(B9:F9) -> 4153876
A10: Operating Tier | B10: =MATCH(B9,INPUTS!C51:C57,1) -> 4 | C10: =MATCH(C9,INPUTS!C51:C57,1) -> 4 | D10: =MATCH(D9,INPUTS!C51:C57,1) -> 5 | E10: =MATCH(E9,INPUTS!C51:C57,1) -> 6 | F10: =MATCH(F9,INPUTS!C51:C57,1) -> 6
A11: Bar COGS/Unit (v3.0) | B11: {=INDEX(CALC_COGS!I7:I13,B10)} -> 1.6401648 | C11: {=INDEX(CALC_COGS!I7:I13,C10)} -> 1.6401648 | D11: {=INDEX(CALC_COGS!I7:I13,D10)} -> 1.4638973 | E11: {=INDEX(CALC_COGS!I7:I13,E10)} -> 1.3889871 | F11: {=INDEX(CALC_COGS!I7:I13,F10)} -> 1.3889871
A12: Elec COGS/Unit (v3.0) | B12: {=INDEX(CALC_COGS!I18:I24,B10)} -> 0.5915048 | C12: {=INDEX(CALC_COGS!I18:I24,C10)} -> 0.5915048 | D12: {=INDEX(CALC_COGS!I18:I24,D10)} -> 0.49695733 | E12: {=INDEX(CALC_COGS!I18:I24,E10)} -> 0.4720471 | F12: {=INDEX(CALC_COGS!I18:I24,F10)} -> 0.4720471
A14: REVENUE
A15: Bars Gross Revenue (annual, no ramp/cap) | B15: =SUMPRODUCT(--(INPUTS!B41:B46="Yes"),B$7*INPUTS!C41:C46/CALC_MONTHLY!$B$3*INPUTS!D41:D46+B$8*INPUTS!C41:C46/CALC_MONTHLY!$B$3*INPUTS!E41:E46) -> 305279.85 | C15: =SUMPRODUCT(--(INPUTS!B41:B46="Yes"),C$7*INPUTS!C41:C46/CALC_MONTHLY!$B$3*INPUTS!D41:D46+C$8*INPUTS!C41:C46/CALC_MONTHLY!$B$3*INPUTS!E41:E46) -> 763201.83 | D15: =SUMPRODUCT(--(INPUTS!B41:B46="Yes"),D$7*INPUTS!C41:C46/CALC_MONTHLY!$B$3*INPUTS!D41:D46+D$8*INPUTS!C41:C46/CALC_MONTHLY!$B$3*INPUTS!E41:E46) -> 1526399.2 | E15: =SUMPRODUCT(--(INPUTS!B41:B46="Yes"),E$7*INPUTS!C41:C46/CALC_MONTHLY!$B$3*INPUTS!D41:D46+E$8*INPUTS!C41:C46/CALC_MONTHLY!$B$3*INPUTS!E41:E46) -> 2549087 | F15: =SUMPRODUCT(--(INPUTS!B41:B46="Yes"),F$7*INPUTS!C41:C46/CALC_MONTHLY!$B$3*INPUTS!D41:D46+F$8*INPUTS!C41:C46/CALC_MONTHLY!$B$3*INPUTS!E41:E46) -> 4078538.8 | G15: =SUM(B15:F15) -> 9222506.7
A16: Returns | B16: =B15*INPUTS!$B$5 -> 6105.597 | C16: =C15*INPUTS!$B$5 -> 15264.037 | D16: =D15*INPUTS!$B$5 -> 30527.985 | E16: =E15*INPUTS!$B$5 -> 50981.74 | F16: =F15*INPUTS!$B$5 -> 81570.776 | G16: =SUM(B16:F16) -> 184450.13
A17: Bars Net Revenue | B17: =B15-B16 -> 299174.25 | C17: =C15-C16 -> 747937.79 | D17: =D15-D16 -> 1495871.3 | E17: =E15-E16 -> 2498105.2 | F17: =F15-F16 -> 3996968 | G17: =SUM(B17:F17) -> 9038056.6
A18: Ingredient Licensing Revenue | B18: =INPUTS!B67 -> 0 | C18: =INPUTS!C67 -> 500000 | D18: =INPUTS!D67 -> 3000000 | E18: =INPUTS!E67 -> 8000000 | F18: =INPUTS!F67 -> 18000000 | G18: =SUM(B18:F18) -> 29500000
A19: TOTAL NET REVENUE | B19: =B17+B18 -> 299174.25 | C19: =C17+C18 -> 1247937.8 | D19: =D17+D18 -> 4495871.3 | E19: =E17+E18 -> 10498105 | F19: =F17+F18 -> 21996968 | G19: =SUM(B19:F19) -> 38538057
A21: COGS
A22: Bars COGS | B22: =B11*B7+B12*B8 -> 155708.12 | C22: =C11*C7+C12*C8 -> 389271.42 | D22: =D11*D7+D12*D8 -> 684559.26 | E22: =E11*E7+E12*E8 -> 1085003 | F22: =F11*F7+F12*F8 -> 1736004.4 | G22: =SUM(B22:F22) -> 4050546.1
A23: Licensing COGS | B23: =B18*INPUTS!$B$68 -> 0 | C23: =C18*INPUTS!$B$68 -> 125000 | D23: =D18*INPUTS!$B$68 -> 750000 | E23: =E18*INPUTS!$B$68 -> 2000000 | F23: =F18*INPUTS!$B$68 -> 4500000 | G23: =SUM(B23:F23) -> 7375000
A24: TOTAL COGS | B24: =B22+B23 -> 155708.12 | C24: =C22+C23 -> 514271.42 | D24: =D22+D23 -> 1434559.3 | E24: =E22+E23 -> 3085003 | F24: =F22+F23 -> 6236004.4 | G24: =SUM(B24:F24) -> 11425546
A25: GROSS PROFIT | B25: =B19-B24 -> 143466.13 | C25: =C19-C24 -> 733666.38 | D25: =D19-D24 -> 3061312 | E25: =E19-E24 -> 7413102.3 | F25: =F19-F24 -> 15760964 | G25: =SUM(B25:F25) -> 27112510
A26: Gross Margin % | B26: =IF(B19=0,0,B25/B19) -> 0.47954037 | C26: =IF(C19=0,0,C25/C19) -> 0.587903 | D26: =IF(D19=0,0,D25/D19) -> 0.68091629 | E26: =IF(E19=0,0,E25/E19) -> 0.70613717 | F26: =IF(F19=0,0,F25/F19) -> 0.71650619
A28: OPEX
A29: Channel Costs | B29: =SUMPRODUCT(--(INPUTS!B41:B46="Yes"),(B$7+B$8)*INPUTS!C41:C46/CALC_MONTHLY!$B$3*INPUTS!F41:F46) -> 84356.25 | C29: =SUMPRODUCT(--(INPUTS!B41:B46="Yes"),(C$7+C$8)*INPUTS!C41:C46/CALC_MONTHLY!$B$3*INPUTS!F41:F46) -> 210891.24 | D29: =SUMPRODUCT(--(INPUTS!B41:B46="Yes"),(D$7+D$8)*INPUTS!C41:C46/CALC_MONTHLY!$B$3*INPUTS!F41:F46) -> 421781.25 | E29: =SUMPRODUCT(--(INPUTS!B41:B46="Yes"),(E$7+E$8)*INPUTS!C41:C46/CALC_MONTHLY!$B$3*INPUTS!F41:F46) -> 704374.69 | F29: =SUMPRODUCT(--(INPUTS!B41:B46="Yes"),(F$7+F$8)*INPUTS!C41:C46/CALC_MONTHLY!$B$3*INPUTS!F41:F46) -> 1126999.5 | G29: =SUM(B29:F29) -> 2548402.9
A30: Fixed Overhead | B30: =(INPUTS!$B$25+INPUTS!$B$26)*12*INPUTS!B66 -> 84000 | C30: =(INPUTS!$B$25+INPUTS!$B$26)*12*INPUTS!C66 -> 126000 | D30: =(INPUTS!$B$25+INPUTS!$B$26)*12*INPUTS!D66 -> 168000 | E30: =(INPUTS!$B$25+INPUTS!$B$26)*12*INPUTS!E66 -> 210000 | F30: =(INPUTS!$B$25+INPUTS!$B$26)*12*INPUTS!F66 -> 252000 | G30: =SUM(B30:F30) -> 840000
A31: Marketing | B31: =INPUTS!B62 -> 150000 | C31: =INPUTS!C62 -> 250000 | D31: =INPUTS!D62 -> 400000 | E31: =INPUTS!E62 -> 600000 | F31: =INPUTS!F62 -> 800000 | G31: =SUM(B31:F31) -> 2200000
A32: Payroll | B32: =INPUTS!B63 -> 200000 | C32: =INPUTS!C63 -> 400000 | D32: =INPUTS!D63 -> 750000 | E32: =INPUTS!E63 -> 1250000 | F32: =INPUTS!F63 -> 1800000 | G32: =SUM(B32:F32) -> 4400000
A33: BD/Sales | B33: =INPUTS!B64 -> 0 | C33: =INPUTS!C64 -> 150000 | D33: =INPUTS!D64 -> 400000 | E33: =INPUTS!E64 -> 800000 | F33: =INPUTS!F64 -> 1500000 | G33: =SUM(B33:F33) -> 2850000
A34: Clinical & IP | B34: =INPUTS!B65 -> 100000 | C34: =INPUTS!C65 -> 200000 | D34: =INPUTS!D65 -> 100000 | E34: =INPUTS!E65 -> 50000 | F34: =INPUTS!F65 -> 50000 | G34: =SUM(B34:F34) -> 500000
A35: G&A | B35: =INPUTS!$B$27*12*INPUTS!B66 -> 72000 | C35: =INPUTS!$B$27*12*INPUTS!C66 -> 108000 | D35: =INPUTS!$B$27*12*INPUTS!D66 -> 144000 | E35: =INPUTS!$B$27*12*INPUTS!E66 -> 180000 | F35: =INPUTS!$B$27*12*INPUTS!F66 -> 216000 | G35: =SUM(B35:F35) -> 720000
A36: Carrying Cost | B36: =B9*INPUTS!$B$8*INPUTS!$B$14 -> 687.5 | C36: =C9*INPUTS!$B$8*INPUTS!$B$14 -> 1718.755 | D36: =D9*INPUTS!$B$8*INPUTS!$B$14 -> 3437.5 | E36: =E9*INPUTS!$B$8*INPUTS!$B$14 -> 5740.625 | F36: =F9*INPUTS!$B$8*INPUTS!$B$14 -> 9185 | G36: =SUM(B36:F36) -> 20769.38
A37: Spoilage Cost | B37: =B7*INPUTS!$B$11*B11*INPUTS!$B$13+B8*INPUTS!$B$12*B12*INPUTS!$B$13 -> 1981.2069 | C37: =C7*INPUTS!$B$11*C11*INPUTS!$B$13+C8*INPUTS!$B$12*C12*INPUTS!$B$13 -> 4953.0314 | D37: =D7*INPUTS!$B$11*D11*INPUTS!$B$13+D8*INPUTS!$B$12*D12*INPUTS!$B$13 -> 8779.5669 | E37: =E7*INPUTS!$B$11*E11*INPUTS!$B$13+E8*INPUTS!$B$12*E12*INPUTS!$B$13 -> 13913.341 | F37: =F7*INPUTS!$B$11*F11*INPUTS!$B$13+F8*INPUTS!$B$12*F12*INPUTS!$B$13 -> 22261.339 | G37: =SUM(B37:F37) -> 51888.485
A38: Commitments | B38: =INPUTS!$C$139*12 -> 66000 | C38: =INPUTS!$C$139*12 -> 66000 | D38: =INPUTS!$C$139*12 -> 66000 | E38: =INPUTS!$C$139*12 -> 66000 | F38: =INPUTS!$C$139*12 -> 66000 | G38: =SUM(B38:F38) -> 330000
A39: Debt Service | B39: =(IF(AND(INPUTS!$B$130>0,INPUTS!$B$132>0),(INPUTS!$B$130*(INPUTS!$B$131/12)*POWER(1+INPUTS!$B$131/12,INPUTS!$B$132))/(POWER(1+INPUTS!$B$131/12,INPUTS!$B$132)-1),0))*12 -> 0 | C39: =(IF(AND(INPUTS!$B$130>0,INPUTS!$B$132>0),(INPUTS!$B$130*(INPUTS!$B$131/12)*POWER(1+INPUTS!$B$131/12,INPUTS!$B$132))/(POWER(1+INPUTS!$B$131/12,INPUTS!$B$132)-1),0))*12 -> 0 | D39: =(IF(AND(INPUTS!$B$130>0,INPUTS!$B$132>0),(INPUTS!$B$130*(INPUTS!$B$131/12)*POWER(1+INPUTS!$B$131/12,INPUTS!$B$132))/(POWER(1+INPUTS!$B$131/12,INPUTS!$B$132)-1),0))*12 -> 0 | E39: =(IF(AND(INPUTS!$B$130>0,INPUTS!$B$132>0),(INPUTS!$B$130*(INPUTS!$B$131/12)*POWER(1+INPUTS!$B$131/12,INPUTS!$B$132))/(POWER(1+INPUTS!$B$131/12,INPUTS!$B$132)-1),0))*12 -> 0 | F39: =(IF(AND(INPUTS!$B$130>0,INPUTS!$B$132>0),(INPUTS!$B$130*(INPUTS!$B$131/12)*POWER(1+INPUTS!$B$131/12,INPUTS!$B$132))/(POWER(1+INPUTS!$B$131/12,INPUTS!$B$132)-1),0))*12 -> 0 | G39: =SUM(B39:F39) -> 0
A40: TOTAL OPEX | B40: =SUM(B29:B39) -> 759024.96 | C40: =SUM(C29:C39) -> 1517563 | D40: =SUM(D29:D39) -> 2461998.3 | E40: =SUM(E29:E39) -> 3880028.7 | F40: =SUM(F29:F39) -> 5842445.8 | G40: =SUM(B40:F40) -> 14461061
A42: EBITDA | B42: =B25-B40 -> -615558.82 | C42: =C25-C40 -> -783896.65 | D42: =D25-D40 -> 599313.68 | E42: =E25-E40 -> 3533073.6 | F42: =F25-F40 -> 9918517.8 | G42: =SUM(B42:F42) -> 12651450
